Workbook

Sheet Resumo 2026
A1: RESUMO ANUAL 2026 — ORÇAMENTO FINANCEIRO
A2: Valores calculados automaticamente a partir das abas mensais • SALDO¹ = valor não quitado nos cartões (nova dívida gerada)
B3: Jan | C3: Fev | D3: Mar | E3: Abr | F3: Mai | G3: Jun | H3: Jul | I3: Ago | J3: Set | K3: Out | L3: Nov | M3: Dez | N3: TOTAL ANO
A4: RECEITA BRUTA | B4: ='Jan'!B20 | C4: ='Fev'!B20 | D4: ='Mar'!B20 | E4: ='Abr'!B20 | F4: ='Mai'!B20 | G4: ='Jun'!B20 | H4: ='Jul'!B20 | I4: ='Ago'!B20 | J4: ='Set'!B20 | K4: ='Out'!B20 | L4: ='Nov'!B20 | M4: ='Dez'!B20 | N4: =SUM(B4:M4)
A5: (−) Descontos em Folha | B5: ='Jan'!F20 | C5: ='Fev'!F20 | D5: ='Mar'!F20 | E5: ='Abr'!F20 | F5: ='Mai'!F20 | G5: ='Jun'!F20 | H5: ='Jul'!F20 | I5: ='Ago'!F20 | J5: ='Set'!F20 | K5: ='Out'!F20 | L5: ='Nov'!F20 | M5: ='Dez'!F20 | N5: =SUM(B5:M5)
A6: =Receita Líquida | B6: ='Jan'!F50 | C6: ='Fev'!F50 | D6: ='Mar'!F50 | E6: ='Abr'!F50 | F6: ='Mai'!F50 | G6: ='Jun'!F50 | H6: ='Jul'!F50 | I6: ='Ago'!F50 | J6: ='Set'!F50 | K6: ='Out'!F50 | L6: ='Nov'!F50 | M6: ='Dez'!F50 | N6: =SUM(B6:M6)
A7: (−) Despesas Fixas CET | B7: ='Jan'!L20 | C7: ='Fev'!L20 | D7: ='Mar'!L20 | E7: ='Abr'!L20 | F7: ='Mai'!L20 | G7: ='Jun'!L20 | H7: ='Jul'!L20 | I7: ='Ago'!L20 | J7: ='Set'!L20 | K7: ='Out'!L20 | L7: ='Nov'!L20 | M7: ='Dez'!L20 | N7: =SUM(B7:M7)
A8: (−) Cartões — Pago | B8: ='Jan'!Q20 | C8: ='Fev'!Q20 | D8: ='Mar'!Q20 | E8: ='Abr'!Q20 | F8: ='Mai'!Q20 | G8: ='Jun'!Q20 | H8: ='Jul'!Q20 | I8: ='Ago'!Q20 | J8: ='Set'!Q20 | K8: ='Out'!Q20 | L8: ='Nov'!Q20 | M8: ='Dez'!Q20 | N8: =SUM(B8:M8)
A9: (−) Juros Cartões | B9: ='Jan'!S20 | C9: ='Fev'!S20 | D9: ='Mar'!S20 | E9: ='Abr'!S20 | F9: ='Mai'!S20 | G9: ='Jun'!S20 | H9: ='Jul'!S20 | I9: ='Ago'!S20 | J9: ='Set'!S20 | K9: ='Out'!S20 | L9: ='Nov'!S20 | M9: ='Dez'!S20 | N9: =SUM(B9:M9)
A10: (−) Juros Cheque Esp. | B10: ='Jan'!D45 | C10: ='Fev'!D45 | D10: ='Mar'!D45 | E10: ='Abr'!D45 | F10: ='Mai'!D45 | G10: ='Jun'!D45 | H10: ='Jul'!D45 | I10: ='Ago'!D45 | J10: ='Set'!D45 | K10: ='Out'!D45 | L10: ='Nov'!D45 | M10: ='Dez'!D45 | N10: =SUM(B10:M10)
A11: (−) Assinaturas | B11: ='Jan'!C36 | C11: ='Fev'!C36 | D11: ='Mar'!C36 | E11: ='Abr'!C36 | F11: ='Mai'!C36 | G11: ='Jun'!C36 | H11: ='Jul'!C36 | I11: ='Ago'!C36 | J11: ='Set'!C36 | K11: ='Out'!C36 | L11: ='Nov'!C36 | M11: ='Dez'!C36 | N11: =SUM(B11:M11)
A12: =SALDO REAL DO MÊS | B12: ='Jan'!F56 | C12: ='Fev'!F56 | D12: ='Mar'!F56 | E12: ='Abr'!F56 | F12: ='Mai'!F56 | G12: ='Jun'!F56 | H12: ='Jul'!F56 | I12: ='Ago'!F56 | J12: ='Set'!F56 | K12: ='Out'!F56 | L12: ='Nov'!F56 | M12: ='Dez'!F56 | N12: =SUM(B12:M12)
A13: Nova Dívida (cartões) | B13: ='Jan'!R20 | C13: ='Fev'!R20 | D13: ='Mar'!R20 | E13: ='Abr'!R20 | F13: ='Mai'!R20 | G13: ='Jun'!R20 | H13: ='Jul'!R20 | I13: ='Ago'!R20 | J13: ='Set'!R20 | K13: ='Out'!R20 | L13: ='Nov'!R20 | M13: ='Dez'!R20 | N13: =SUM(B13:M13)
A14: Total em Contas | B14: ='Jan'!B78 | C14: ='Fev'!B78 | D14: ='Mar'!B78 | E14: ='Abr'!B78 | F14: ='Mai'!B78 | G14: ='Jun'!B78 | H14: ='Jul'!B78 | I14: ='Ago'!B78 | J14: ='Set'!B78 | K14: ='Out'!B78 | L14: ='Nov'!B78 | M14: ='Dez'!B78 | N14: =SUM(B14:M14)

Sheet Jan
A1: ORÇAMENTO JANEIRO 2026
A2: ▶ FONTES DE RECEITA | E2: ▶ DESCONTOS EM FOLHA | I2: ▶ DESPESAS FIXAS | O2: ▶ DESPESAS COM CARTÕES
A3: ORIGEM | B3: VALOR | C3: SITUAÇÃO | D3: DATA PG | E3: ORIGEM | F3: VALOR | G3: INFO | H3: OBS | I3: ORIGEM | J3: VALOR | K3: JUROS | L3: CET | M3: SITUAÇÃO | N3: DATA PG | O3: CARTÃO | P3: FATURA | Q3: PAGO | R3: SALDO¹ | S3: JUROS | T3: CET | U3: SITUAÇÃO | V3: DATA PG
A4: SALÁRIO | E4: Consignado V.Nbk | I4: HAPVIDA/SALMINHO | L4: =IF(J4="","",J4+IF(K4="",0,K4)) | O4: BB | R4: =IF(P4="","",P4-IF(Q4="",0,Q4)) | T4: =IF(Q4="","",Q4+IF(S4="",0,S4))
A5: Kalena OF/NET | E5: Caixa Habitação | I5: HAPVIDA/SABRINA | L5: =IF(J5="","",J5+IF(K5="",0,K5)) | O5: NU | R5: =IF(P5="","",P5-IF(Q5="",0,Q5)) | T5: =IF(Q5="","",Q5+IF(S5="",0,S5))
A6: ALUGUÉL | E6: Consignado BB | I6: HAP EWE E EFRA | L6: =IF(J6="","",J6+IF(K6="",0,K6)) | O6: Santander SX | R6: =IF(P6="","",P6-IF(Q6="",0,Q6)) | T6: =IF(Q6="","",Q6+IF(S6="",0,S6))
A7: Wagner | E7: Emp.Sal.BB | I7: CELPA ENERGIA | L7: =IF(J7="","",J7+IF(K7="",0,K7)) | O7: SELITE | R7: =IF(P7="","",P7-IF(Q7="",0,Q7)) | T7: =IF(Q7="","",Q7+IF(S7="",0,S7))
A8: Neto | E8: AUX.TRANSP | I8: SEATELECOM | L8: =IF(J8="","",J8+IF(K8="",0,K8)) | O8: Caixa Gold | R8: =IF(P8="","",P8-IF(Q8="",0,Q8)) | T8: =IF(Q8="","",Q8+IF(S8="",0,S8))
A9: UAB | E9: CONTRI.SOCIAL | I9: TX.ÁLAMO | L9: =IF(J9="","",J9+IF(K9="",0,K9)) | O9: Cartão MP | R9: =IF(P9="","",P9-IF(Q9="",0,Q9)) | T9: =IF(Q9="","",Q9+IF(S9="",0,S9))
E10: IRRF | I10: CONTA TIM | L10: =IF(J10="","",J10+IF(K10="",0,K10)) | O10: PicPay Card | R10: =IF(P10="","",P10-IF(Q10="",0,Q10)) | T10: =IF(Q10="","",Q10+IF(S10="",0,S10))
E11: AUX.PRÉ.ESC | I11: CONTA CLARO | L11: =IF(J11="","",J11+IF(K11="",0,K11)) | O11: Itaú Card | R11: =IF(P11="","",P11-IF(Q11="",0,Q11)) | T11: =IF(Q11="","",Q11+IF(S11="",0,S11))
E12: Dízimo | I12: MAXÍDOMINI | L12: =IF(J12="","",J12+IF(K12="",0,K12)) | O12: CAIXA ELO | R12: =IF(P12="","",P12-IF(Q12="",0,Q12)) | T12: =IF(Q12="","",Q12+IF(S12="",0,S12))
I13: COSANPA/ÁGUA | L13: =IF(J13="","",J13+IF(K13="",0,K13)) | O13: Bradesco | R13: =IF(P13="","",P13-IF(Q13="",0,Q13)) | T13: =IF(Q13="","",Q13+IF(S13="",0,S13))
I14: ESCOLA SALMOM | L14: =IF(J14="","",J14+IF(K14="",0,K14)) | O14: RecargaPay | R14: =IF(P14="","",P14-IF(Q14="",0,Q14)) | T14: =IF(Q14="","",Q14+IF(S14="",0,S14))
I15: CORECON | L15: =IF(J15="","",J15+IF(K15="",0,K15)) | O15: BipaCard | R15: =IF(P15="","",P15-IF(Q15="",0,Q15)) | T15: =IF(Q15="","",Q15+IF(S15="",0,S15))
I16: Boticário | L16: =IF(J16="","",J16+IF(K16="",0,K16)) | O16: InfinitCard | R16: =IF(P16="","",P16-IF(Q16="",0,Q16)) | T16: =IF(Q16="","",Q16+IF(S16="",0,S16))
I17: Rodobens | L17: =IF(J17="","",J17+IF(K17="",0,K17)) | O17: Pagbank | R17: =IF(P17="","",P17-IF(Q17="",0,Q17)) | T17: =IF(Q17="","",Q17+IF(S17="",0,S17))
L18: =IF(J18="","",J18+IF(K18="",0,K18)) | O18: TonCard | R18: =IF(P18="","",P18-IF(Q18="",0,Q18)) | T18: =IF(Q18="","",Q18+IF(S18="",0,S18))
L19: =IF(J19="","",J19+IF(K19="",0,K19)) | R19: =IF(P19="","",P19-IF(Q19="",0,Q19)) | T19: =IF(Q19="","",Q19+IF(S19="",0,S19))
A20: RECEITA TOTAL | B20: =SUM(B4:B19) | E20: TOTAL DESCONTOS | F20: =SUM(F4:F19) | I20: TOTAL FIXAS (CET) | J20: =SUM(J4:J19) | K20: =SUM(K4:K19) | L20: =SUM(L4:L19) | O20: TOTAL CARTÕES | P20: =SUM(P4:P19) | Q20: =SUM(Q4:Q19) | R20: =SUM(R4:R19) | S20: =SUM(S4:S19) | T20: =SUM(T4:T19)
O21: ¹ SALDO = Fatura − Pago (valor não quitado = nova dívida do mês)
A22: ASSINATURAS ONLINE | F22: NOTAS / EMPRÉSTIMOS / CONSIGNADOS
A23: CARTÃO | B23: SERVIÇO | C23: VALOR | D23: DIA/SITUAÇÃO | F23: DESCRIÇÃO | G23: TAXA (am) | H23: TAXA (aa) | I23: OBS / SALDO
A24: NU | B24: GDRIVE SABRI | C24: 49.9 | D24: DIA 04 — CRÉDITO (NU) | F24: Consignado Nubank 1 | G24: 1.30% am | H24: 16.74% aa | I24: 73x
A25: NU | B25: CONTA TIM | C25: 42 | D25: DIA 15 — PG MANUAL | F25: Consignado Nubank 2 | G25: 1.57% am | H25: 21.85% aa | I25: 96x — saldo R$776,82
A26: SANTANDER SX | B26: PLANO CLARO | C26: 73.73 | D26: DIA 09 — PG MANUAL | F26: Fin. Habitação CAIXA | G26: 7% nominal
A27: NU | B27: YOUTUBE ST | C27: 53.9 | D27: DIA 25 — CRÉDITO (NU) | F27: Empréstimo Sabrina | I27: saldo R$2.503,46
A28: NU | B28: ICLOUD | C28: 5.9 | D28: DIA 01 — CRÉDITO (NU) | F28: Empréstimo Josy
B29: Serasa | C29: 23.9 | D29: DIA 17 —
B30: Kindle | C30: 24
A31: NU | B31: GPT | C31: 130 | D31: DIA 02 — CRÉDITO (NU)
A32: NU | B32: Copilot | C32: 109.9 | D32: DIA 04 — CRÉDITO (NU)
A33: NU | B33: WORD | C33: 0 | D33: Anual — CRÉDITO (NU)
A34: NU | B34: GDRIVE EWE | C34: 0 | D34: Ago/26 — CRÉDITO (NU)
B35: PDFVIEW | C35: 0 | D35: CRÉDITO (NU)
A36: TOTAL ASSINATURAS | C36: =SUM(C24:C35)
A38: CHEQUE ESPECIAL / DÍVIDAS FINANCEIRAS
A39: BANCO | B39: LIMITE | C39: USADO | D39: JUROS MÊS | E39: TAXA % aa | F39: DIAS | G39: SITUAÇÃO
A40: BB
A41: Santander
...

Sheet Fev
A1: ORÇAMENTO FEVEREIRO 2026
A2: ▶ FONTES DE RECEITA | E2: ▶ DESCONTOS EM FOLHA | I2: ▶ DESPESAS FIXAS | O2: ▶ DESPESAS COM CARTÕES
A3: ORIGEM | B3: VALOR | C3: SITUAÇÃO | D3: DATA PG | E3: ORIGEM | F3: VALOR | G3: INFO | H3: OBS | I3: ORIGEM | J3: VALOR | K3: JUROS | L3: CET | M3: SITUAÇÃO | N3: DATA PG | O3: CARTÃO | P3: FATURA | Q3: PAGO | R3: SALDO¹ | S3: JUROS | T3: CET | U3: SITUAÇÃO | V3: DATA PG
A4: SALÁRIO | E4: Consignado V.Nbk | I4: HAPVIDA/SALMINHO | L4: =IF(J4="","",J4+IF(K4="",0,K4)) | O4: BB | R4: =IF(P4="","",P4-IF(Q4="",0,Q4)) | T4: =IF(Q4="","",Q4+IF(S4="",0,S4))
A5: Kalena OF/NET | E5: Caixa Habitação | I5: HAPVIDA/SABRINA | L5: =IF(J5="","",J5+IF(K5="",0,K5)) | O5: NU | R5: =IF(P5="","",P5-IF(Q5="",0,Q5)) | T5: =IF(Q5="","",Q5+IF(S5="",0,S5))
A6: ALUGUÉL | E6: Consignado BB | I6: HAP EWE E EFRA | L6: =IF(J6="","",J6+IF(K6="",0,K6)) | O6: Santander SX | R6: =IF(P6="","",P6-IF(Q6="",0,Q6)) | T6: =IF(Q6="","",Q6+IF(S6="",0,S6))
A7: Wagner | E7: Emp.Sal.BB | I7: CELPA ENERGIA | L7: =IF(J7="","",J7+IF(K7="",0,K7)) | O7: SELITE | R7: =IF(P7="","",P7-IF(Q7="",0,Q7)) | T7: =IF(Q7="","",Q7+IF(S7="",0,S7))
A8: Neto | E8: AUX.TRANSP | I8: SEATELECOM | L8: =IF(J8="","",J8+IF(K8="",0,K8)) | O8: Caixa Gold | R8: =IF(P8="","",P8-IF(Q8="",0,Q8)) | T8: =IF(Q8="","",Q8+IF(S8="",0,S8))
A9: UAB | E9: CONTRI.SOCIAL | I9: TX.ÁLAMO | L9: =IF(J9="","",J9+IF(K9="",0,K9)) | O9: Cartão MP | R9: =IF(P9="","",P9-IF(Q9="",0,Q9)) | T9: =IF(Q9="","",Q9+IF(S9="",0,S9))
E10: IRRF | I10: CONTA TIM | L10: =IF(J10="","",J10+IF(K10="",0,K10)) | O10: PicPay Card | R10: =IF(P10="","",P10-IF(Q10="",0,Q10)) | T10: =IF(Q10="","",Q10+IF(S10="",0,S10))
E11: AUX.PRÉ.ESC | I11: CONTA CLARO | L11: =IF(J11="","",J11+IF(K11="",0,K11)) | O11: Itaú Card | R11: =IF(P11="","",P11-IF(Q11="",0,Q11)) | T11: =IF(Q11="","",Q11+IF(S11="",0,S11))
E12: Dízimo | I12: MAXÍDOMINI | L12: =IF(J12="","",J12+IF(K12="",0,K12)) | O12: CAIXA ELO | R12: =IF(P12="","",P12-IF(Q12="",0,Q12)) | T12: =IF(Q12="","",Q12+IF(S12="",0,S12))
I13: COSANPA/ÁGUA | L13: =IF(J13="","",J13+IF(K13="",0,K13)) | O13: Bradesco | R13: =IF(P13="","",P13-IF(Q13="",0,Q13)) | T13: =IF(Q13="","",Q13+IF(S13="",0,S13))
I14: ESCOLA SALMOM | L14: =IF(J14="","",J14+IF(K14="",0,K14)) | O14: RecargaPay | R14: =IF(P14="","",P14-IF(Q14="",0,Q14)) | T14: =IF(Q14="","",Q14+IF(S14="",0,S14))
I15: CORECON | L15: =IF(J15="","",J15+IF(K15="",0,K15)) | O15: BipaCard | R15: =IF(P15="","",P15-IF(Q15="",0,Q15)) | T15: =IF(Q15="","",Q15+IF(S15="",0,S15))
I16: Boticário | L16: =IF(J16="","",J16+IF(K16="",0,K16)) | O16: InfinitCard | R16: =IF(P16="","",P16-IF(Q16="",0,Q16)) | T16: =IF(Q16="","",Q16+IF(S16="",0,S16))
I17: Rodobens | L17: =IF(J17="","",J17+IF(K17="",0,K17)) | O17: Pagbank | R17: =IF(P17="","",P17-IF(Q17="",0,Q17)) | T17: =IF(Q17="","",Q17+IF(S17="",0,S17))
L18: =IF(J18="","",J18+IF(K18="",0,K18)) | O18: TonCard | R18: =IF(P18="","",P18-IF(Q18="",0,Q18)) | T18: =IF(Q18="","",Q18+IF(S18="",0,S18))
L19: =IF(J19="","",J19+IF(K19="",0,K19)) | R19: =IF(P19="","",P19-IF(Q19="",0,Q19)) | T19: =IF(Q19="","",Q19+IF(S19="",0,S19))
A20: RECEITA TOTAL | B20: =SUM(B4:B19) | E20: TOTAL DESCONTOS | F20: =SUM(F4:F19) | I20: TOTAL FIXAS (CET) | J20: =SUM(J4:J19) | K20: =SUM(K4:K19) | L20: =SUM(L4:L19) | O20: TOTAL CARTÕES | P20: =SUM(P4:P19) | Q20: =SUM(Q4:Q19) | R20: =SUM(R4:R19) | S20: =SUM(S4:S19) | T20: =SUM(T4:T19)
O21: ¹ SALDO = Fatura − Pago (valor não quitado = nova dívida do mês)
A22: ASSINATURAS ONLINE | F22: NOTAS / EMPRÉSTIMOS / CONSIGNADOS
A23: CARTÃO | B23: SERVIÇO | C23: VALOR | D23: DIA/SITUAÇÃO | F23: DESCRIÇÃO | G23: TAXA (am) | H23: TAXA (aa) | I23: OBS / SALDO
A24: NU | B24: GDRIVE SABRI | C24: 49.9 | D24: DIA 04 — CRÉDITO (NU) | F24: Consignado Nubank 1 | G24: 1.30% am | H24: 16.74% aa | I24: 73x
A25: NU | B25: CONTA TIM | C25: 42 | D25: DIA 15 — PG MANUAL | F25: Consignado Nubank 2 | G25: 1.57% am | H25: 21.85% aa | I25: 96x — saldo R$776,82
A26: SANTANDER SX | B26: PLANO CLARO | C26: 73.73 | D26: DIA 09 — PG MANUAL | F26: Fin. Habitação CAIXA | G26: 7% nominal
A27: NU | B27: YOUTUBE ST | C27: 53.9 | D27: DIA 25 — CRÉDITO (NU) | F27: Empréstimo Sabrina | I27: saldo R$2.503,46
A28: NU | B28: ICLOUD | C28: 5.9 | D28: DIA 01 — CRÉDITO (NU) | F28: Empréstimo Josy
B29: Serasa | C29: 23.9 | D29: DIA 17 —
B30: Kindle | C30: 24
A31: NU | B31: GPT | C31: 130 | D31: DIA 02 — CRÉDITO (NU)
A32: NU | B32: Copilot | C32: 109.9 | D32: DIA 04 — CRÉDITO (NU)
A33: NU | B33: WORD | C33: 0 | D33: Anual — CRÉDITO (NU)
A34: NU | B34: GDRIVE EWE | C34: 0 | D34: Ago/26 — CRÉDITO (NU)
B35: PDFVIEW | C35: 0 | D35: CRÉDITO (NU)
A36: TOTAL ASSINATURAS | C36: =SUM(C24:C35)
A38: CHEQUE ESPECIAL / DÍVIDAS FINANCEIRAS
A39: BANCO | B39: LIMITE | C39: USADO | D39: JUROS MÊS | E39: TAXA % aa | F39: DIAS | G39: SITUAÇÃO
A40: BB
A41: Santander
...

Sheet Mar
A1: ORÇAMENTO MARÇO 2026
A2: ▶ FONTES DE RECEITA | E2: ▶ DESCONTOS EM FOLHA | I2: ▶ DESPESAS FIXAS | O2: ▶ DESPESAS COM CARTÕES
A3: ORIGEM | B3: VALOR | C3: SITUAÇÃO | D3: DATA PG | E3: ORIGEM | F3: VALOR | G3: INFO | H3: OBS | I3: ORIGEM | J3: VALOR | K3: JUROS | L3: CET | M3: SITUAÇÃO | N3: DATA PG | O3: CARTÃO | P3: FATURA | Q3: PAGO | R3: SALDO¹ | S3: JUROS | T3: CET | U3: SITUAÇÃO | V3: DATA PG
A4: SALÁRIO | E4: Consignado V.Nbk | I4: HAPVIDA/SALMINHO | L4: =IF(J4="","",J4+IF(K4="",0,K4)) | O4: BB | R4: =IF(P4="","",P4-IF(Q4="",0,Q4)) | T4: =IF(Q4="","",Q4+IF(S4="",0,S4))
A5: Kalena OF/NET | E5: Caixa Habitação | I5: HAPVIDA/SABRINA | L5: =IF(J5="","",J5+IF(K5="",0,K5)) | O5: NU | R5: =IF(P5="","",P5-IF(Q5="",0,Q5)) | T5: =IF(Q5="","",Q5+IF(S5="",0,S5))
A6: ALUGUÉL | E6: Consignado BB | I6: HAP EWE E EFRA | L6: =IF(J6="","",J6+IF(K6="",0,K6)) | O6: Santander SX | R6: =IF(P6="","",P6-IF(Q6="",0,Q6)) | T6: =IF(Q6="","",Q6+IF(S6="",0,S6))
A7: Wagner | E7: Emp.Sal.BB | I7: CELPA ENERGIA | L7: =IF(J7="","",J7+IF(K7="",0,K7)) | O7: SELITE | R7: =IF(P7="","",P7-IF(Q7="",0,Q7)) | T7: =IF(Q7="","",Q7+IF(S7="",0,S7))
A8: Neto | E8: AUX.TRANSP | I8: SEATELECOM | L8: =IF(J8="","",J8+IF(K8="",0,K8)) | O8: Caixa Gold | R8: =IF(P8="","",P8-IF(Q8="",0,Q8)) | T8: =IF(Q8="","",Q8+IF(S8="",0,S8))
A9: UAB | E9: CONTRI.SOCIAL | I9: TX.ÁLAMO | L9: =IF(J9="","",J9+IF(K9="",0,K9)) | O9: Cartão MP | R9: =IF(P9="","",P9-IF(Q9="",0,Q9)) | T9: =IF(Q9="","",Q9+IF(S9="",0,S9))
E10: IRRF | I10: CONTA TIM | L10: =IF(J10="","",J10+IF(K10="",0,K10)) | O10: PicPay Card | R10: =IF(P10="","",P10-IF(Q10="",0,Q10)) | T10: =IF(Q10="","",Q10+IF(S10="",0,S10))
E11: AUX.PRÉ.ESC | I11: CONTA CLARO | L11: =IF(J11="","",J11+IF(K11="",0,K11)) | O11: Itaú Card | R11: =IF(P11="","",P11-IF(Q11="",0,Q11)) | T11: =IF(Q11="","",Q11+IF(S11="",0,S11))
E12: Dízimo | I12: MAXÍDOMINI | L12: =IF(J12="","",J12+IF(K12="",0,K12)) | O12: CAIXA ELO | R12: =IF(P12="","",P12-IF(Q12="",0,Q12)) | T12: =IF(Q12="","",Q12+IF(S12="",0,S12))
I13: COSANPA/ÁGUA | L13: =IF(J13="","",J13+IF(K13="",0,K13)) | O13: Bradesco | R13: =IF(P13="","",P13-IF(Q13="",0,Q13)) | T13: =IF(Q13="","",Q13+IF(S13="",0,S13))
I14: ESCOLA SALMOM | L14: =IF(J14="","",J14+IF(K14="",0,K14)) | O14: RecargaPay | R14: =IF(P14="","",P14-IF(Q14="",0,Q14)) | T14: =IF(Q14="","",Q14+IF(S14="",0,S14))
I15: CORECON | L15: =IF(J15="","",J15+IF(K15="",0,K15)) | O15: BipaCard | R15: =IF(P15="","",P15-IF(Q15="",0,Q15)) | T15: =IF(Q15="","",Q15+IF(S15="",0,S15))
I16: Boticário | L16: =IF(J16="","",J16+IF(K16="",0,K16)) | O16: InfinitCard | R16: =IF(P16="","",P16-IF(Q16="",0,Q16)) | T16: =IF(Q16="","",Q16+IF(S16="",0,S16))
I17: Rodobens | L17: =IF(J17="","",J17+IF(K17="",0,K17)) | O17: Pagbank | R17: =IF(P17="","",P17-IF(Q17="",0,Q17)) | T17: =IF(Q17="","",Q17+IF(S17="",0,S17))
L18: =IF(J18="","",J18+IF(K18="",0,K18)) | O18: TonCard | R18: =IF(P18="","",P18-IF(Q18="",0,Q18)) | T18: =IF(Q18="","",Q18+IF(S18="",0,S18))
L19: =IF(J19="","",J19+IF(K19="",0,K19)) | R19: =IF(P19="","",P19-IF(Q19="",0,Q19)) | T19: =IF(Q19="","",Q19+IF(S19="",0,S19))
A20: RECEITA TOTAL | B20: =SUM(B4:B19) | E20: TOTAL DESCONTOS | F20: =SUM(F4:F19) | I20: TOTAL FIXAS (CET) | J20: =SUM(J4:J19) | K20: =SUM(K4:K19) | L20: =SUM(L4:L19) | O20: TOTAL CARTÕES | P20: =SUM(P4:P19) | Q20: =SUM(Q4:Q19) | R20: =SUM(R4:R19) | S20: =SUM(S4:S19) | T20: =SUM(T4:T19)
O21: ¹ SALDO = Fatura − Pago (valor não quitado = nova dívida do mês)
A22: ASSINATURAS ONLINE | F22: NOTAS / EMPRÉSTIMOS / CONSIGNADOS
A23: CARTÃO | B23: SERVIÇO | C23: VALOR | D23: DIA/SITUAÇÃO | F23: DESCRIÇÃO | G23: TAXA (am) | H23: TAXA (aa) | I23: OBS / SALDO
A24: NU | B24: GDRIVE SABRI | C24: 49.9 | D24: DIA 04 — CRÉDITO (NU) | F24: Consignado Nubank 1 | G24: 1.30% am | H24: 16.74% aa | I24: 73x
A25: NU | B25: CONTA TIM | C25: 42 | D25: DIA 15 — PG MANUAL | F25: Consignado Nubank 2 | G25: 1.57% am | H25: 21.85% aa | I25: 96x — saldo R$776,82
A26: SANTANDER SX | B26: PLANO CLARO | C26: 73.73 | D26: DIA 09 — PG MANUAL | F26: Fin. Habitação CAIXA | G26: 7% nominal
A27: NU | B27: YOUTUBE ST | C27: 53.9 | D27: DIA 25 — CRÉDITO (NU) | F27: Empréstimo Sabrina | I27: saldo R$2.503,46
A28: NU | B28: ICLOUD | C28: 5.9 | D28: DIA 01 — CRÉDITO (NU) | F28: Empréstimo Josy
B29: Serasa | C29: 23.9 | D29: DIA 17 —
B30: Kindle | C30: 24
A31: NU | B31: GPT | C31: 130 | D31: DIA 02 — CRÉDITO (NU)
A32: NU | B32: Copilot | C32: 109.9 | D32: DIA 04 — CRÉDITO (NU)
A33: NU | B33: WORD | C33: 0 | D33: Anual — CRÉDITO (NU)
A34: NU | B34: GDRIVE EWE | C34: 0 | D34: Ago/26 — CRÉDITO (NU)
B35: PDFVIEW | C35: 0 | D35: CRÉDITO (NU)
A36: TOTAL ASSINATURAS | C36: =SUM(C24:C35)
A38: CHEQUE ESPECIAL / DÍVIDAS FINANCEIRAS
A39: BANCO | B39: LIMITE | C39: USADO | D39: JUROS MÊS | E39: TAXA % aa | F39: DIAS | G39: SITUAÇÃO
A40: BB
A41: Santander
...

Sheet Abr
A1: ORÇAMENTO ABRIL 2026
A2: ▶ FONTES DE RECEITA | E2: ▶ DESCONTOS EM FOLHA | I2: ▶ DESPESAS FIXAS | O2: ▶ DESPESAS COM CARTÕES
A3: ORIGEM | B3: VALOR | C3: SITUAÇÃO | D3: DATA PG | E3: ORIGEM | F3: VALOR | G3: INFO | H3: OBS | I3: ORIGEM | J3: VALOR | K3: JUROS | L3: CET | M3: SITUAÇÃO | N3: DATA PG | O3: CARTÃO | P3: FATURA | Q3: PAGO | R3: SALDO¹ | S3: JUROS | T3: CET | U3: SITUAÇÃO | V3: DATA PG
A4: SALÁRIO | E4: Consignado V.Nbk | I4: HAPVIDA/SALMINHO | L4: =IF(J4="","",J4+IF(K4="",0,K4)) | O4: BB | R4: =IF(P4="","",P4-IF(Q4="",0,Q4)) | T4: =IF(Q4="","",Q4+IF(S4="",0,S4))
A5: Kalena OF/NET | E5: Caixa Habitação | I5: HAPVIDA/SABRINA | L5: =IF(J5="","",J5+IF(K5="",0,K5)) | O5: NU | R5: =IF(P5="","",P5-IF(Q5="",0,Q5)) | T5: =IF(Q5="","",Q5+IF(S5="",0,S5))
A6: ALUGUÉL | E6: Consignado BB | I6: HAP EWE E EFRA | L6: =IF(J6="","",J6+IF(K6="",0,K6)) | O6: Santander SX | R6: =IF(P6="","",P6-IF(Q6="",0,Q6)) | T6: =IF(Q6="","",Q6+IF(S6="",0,S6))
A7: Wagner | E7: Emp.Sal.BB | I7: CELPA ENERGIA | L7: =IF(J7="","",J7+IF(K7="",0,K7)) | O7: SELITE | R7: =IF(P7="","",P7-IF(Q7="",0,Q7)) | T7: =IF(Q7="","",Q7+IF(S7="",0,S7))
A8: Neto | E8: AUX.TRANSP | I8: SEATELECOM | L8: =IF(J8="","",J8+IF(K8="",0,K8)) | O8: Caixa Gold | R8: =IF(P8="","",P8-IF(Q8="",0,Q8)) | T8: =IF(Q8="","",Q8+IF(S8="",0,S8))
A9: UAB | E9: CONTRI.SOCIAL | I9: TX.ÁLAMO | L9: =IF(J9="","",J9+IF(K9="",0,K9)) | O9: Cartão MP | R9: =IF(P9="","",P9-IF(Q9="",0,Q9)) | T9: =IF(Q9="","",Q9+IF(S9="",0,S9))
E10: IRRF | I10: CONTA TIM | L10: =IF(J10="","",J10+IF(K10="",0,K10)) | O10: PicPay Card | R10: =IF(P10="","",P10-IF(Q10="",0,Q10)) | T10: =IF(Q10="","",Q10+IF(S10="",0,S10))
E11: AUX.PRÉ.ESC | I11: CONTA CLARO | L11: =IF(J11="","",J11+IF(K11="",0,K11)) | O11: Itaú Card | R11: =IF(P11="","",P11-IF(Q11="",0,Q11)) | T11: =IF(Q11="","",Q11+IF(S11="",0,S11))
E12: Dízimo | I12: MAXÍDOMINI | L12: =IF(J12="","",J12+IF(K12="",0,K12)) | O12: CAIXA ELO | R12: =IF(P12="","",P12-IF(Q12="",0,Q12)) | T12: =IF(Q12="","",Q12+IF(S12="",0,S12))
I13: COSANPA/ÁGUA | L13: =IF(J13="","",J13+IF(K13="",0,K13)) | O13: Bradesco | R13: =IF(P13="","",P13-IF(Q13="",0,Q13)) | T13: =IF(Q13="","",Q13+IF(S13="",0,S13))
I14: ESCOLA SALMOM | L14: =IF(J14="","",J14+IF(K14="",0,K14)) | O14: RecargaPay | R14: =IF(P14="","",P14-IF(Q14="",0,Q14)) | T14: =IF(Q14="","",Q14+IF(S14="",0,S14))
I15: CORECON | L15: =IF(J15="","",J15+IF(K15="",0,K15)) | O15: BipaCard | R15: =IF(P15="","",P15-IF(Q15="",0,Q15)) | T15: =IF(Q15="","",Q15+IF(S15="",0,S15))
I16: Boticário | L16: =IF(J16="","",J16+IF(K16="",0,K16)) | O16: InfinitCard | R16: =IF(P16="","",P16-IF(Q16="",0,Q16)) | T16: =IF(Q16="","",Q16+IF(S16="",0,S16))
I17: Rodobens | L17: =IF(J17="","",J17+IF(K17="",0,K17)) | O17: Pagbank | R17: =IF(P17="","",P17-IF(Q17="",0,Q17)) | T17: =IF(Q17="","",Q17+IF(S17="",0,S17))
L18: =IF(J18="","",J18+IF(K18="",0,K18)) | O18: TonCard | R18: =IF(P18="","",P18-IF(Q18="",0,Q18)) | T18: =IF(Q18="","",Q18+IF(S18="",0,S18))
L19: =IF(J19="","",J19+IF(K19="",0,K19)) | R19: =IF(P19="","",P19-IF(Q19="",0,Q19)) | T19: =IF(Q19="","",Q19+IF(S19="",0,S19))
A20: RECEITA TOTAL | B20: =SUM(B4:B19) | E20: TOTAL DESCONTOS | F20: =SUM(F4:F19) | I20: TOTAL FIXAS (CET) | J20: =SUM(J4:J19) | K20: =SUM(K4:K19) | L20: =SUM(L4:L19) | O20: TOTAL CARTÕES | P20: =SUM(P4:P19) | Q20: =SUM(Q4:Q19) | R20: =SUM(R4:R19) | S20: =SUM(S4:S19) | T20: =SUM(T4:T19)
O21: ¹ SALDO = Fatura − Pago (valor não quitado = nova dívida do mês)
A22: ASSINATURAS ONLINE | F22: NOTAS / EMPRÉSTIMOS / CONSIGNADOS
A23: CARTÃO | B23: SERVIÇO | C23: VALOR | D23: DIA/SITUAÇÃO | F23: DESCRIÇÃO | G23: TAXA (am) | H23: TAXA (aa) | I23: OBS / SALDO
A24: NU | B24: GDRIVE SABRI | C24: 49.9 | D24: DIA 04 — CRÉDITO (NU) | F24: Consignado Nubank 1 | G24: 1.30% am | H24: 16.74% aa | I24: 73x
A25: NU | B25: CONTA TIM | C25: 42 | D25: DIA 15 — PG MANUAL | F25: Consignado Nubank 2 | G25: 1.57% am | H25: 21.85% aa | I25: 96x — saldo R$776,82
A26: SANTANDER SX | B26: PLANO CLARO | C26: 73.73 | D26: DIA 09 — PG MANUAL | F26: Fin. Habitação CAIXA | G26: 7% nominal
A27: NU | B27: YOUTUBE ST | C27: 53.9 | D27: DIA 25 — CRÉDITO (NU) | F27: Empréstimo Sabrina | I27: saldo R$2.503,46
A28: NU | B28: ICLOUD | C28: 5.9 | D28: DIA 01 — CRÉDITO (NU) | F28: Empréstimo Josy
B29: Serasa | C29: 23.9 | D29: DIA 17 —
B30: Kindle | C30: 24
A31: NU | B31: GPT | C31: 130 | D31: DIA 02 — CRÉDITO (NU)
A32: NU | B32: Copilot | C32: 109.9 | D32: DIA 04 — CRÉDITO (NU)
A33: NU | B33: WORD | C33: 0 | D33: Anual — CRÉDITO (NU)
A34: NU | B34: GDRIVE EWE | C34: 0 | D34: Ago/26 — CRÉDITO (NU)
B35: PDFVIEW | C35: 0 | D35: CRÉDITO (NU)
A36: TOTAL ASSINATURAS | C36: =SUM(C24:C35)
A38: CHEQUE ESPECIAL / DÍVIDAS FINANCEIRAS
A39: BANCO | B39: LIMITE | C39: USADO | D39: JUROS MÊS | E39: TAXA % aa | F39: DIAS | G39: SITUAÇÃO
A40: BB
A41: Santander
...

Sheet Mai
A1: ORÇAMENTO MAIO 2026
A2: ▶ FONTES DE RECEITA | E2: ▶ DESCONTOS EM FOLHA | I2: ▶ DESPESAS FIXAS | O2: ▶ DESPESAS COM CARTÕES
A3: ORIGEM | B3: VALOR | C3: SITUAÇÃO | D3: DATA PG | E3: ORIGEM | F3: VALOR | G3: INFO | H3: OBS | I3: ORIGEM | J3: VALOR | K3: JUROS | L3: CET | M3: SITUAÇÃO | N3: DATA PG | O3: CARTÃO | P3: FATURA | Q3: PAGO | R3: SALDO¹ | S3: JUROS | T3: CET | U3: SITUAÇÃO | V3: DATA PG
A4: SALÁRIO | E4: Consignado V.Nbk | I4: HAPVIDA/SALMINHO | L4: =IF(J4="","",J4+IF(K4="",0,K4)) | O4: BB | R4: =IF(P4="","",P4-IF(Q4="",0,Q4)) | T4: =IF(Q4="","",Q4+IF(S4="",0,S4))
A5: Kalena OF/NET | E5: Caixa Habitação | I5: HAPVIDA/SABRINA | L5: =IF(J5="","",J5+IF(K5="",0,K5)) | O5: NU | R5: =IF(P5="","",P5-IF(Q5="",0,Q5)) | T5: =IF(Q5="","",Q5+IF(S5="",0,S5))
A6: ALUGUÉL | E6: Consignado BB | I6: HAP EWE E EFRA | L6: =IF(J6="","",J6+IF(K6="",0,K6)) | O6: Santander SX | R6: =IF(P6="","",P6-IF(Q6="",0,Q6)) | T6: =IF(Q6="","",Q6+IF(S6="",0,S6))
A7: Wagner | E7: Emp.Sal.BB | I7: CELPA ENERGIA | L7: =IF(J7="","",J7+IF(K7="",0,K7)) | O7: SELITE | R7: =IF(P7="","",P7-IF(Q7="",0,Q7)) | T7: =IF(Q7="","",Q7+IF(S7="",0,S7))
A8: Neto | E8: AUX.TRANSP | I8: SEATELECOM | L8: =IF(J8="","",J8+IF(K8="",0,K8)) | O8: Caixa Gold | R8: =IF(P8="","",P8-IF(Q8="",0,Q8)) | T8: =IF(Q8="","",Q8+IF(S8="",0,S8))
A9: UAB | E9: CONTRI.SOCIAL | I9: TX.ÁLAMO | L9: =IF(J9="","",J9+IF(K9="",0,K9)) | O9: Cartão MP | R9: =IF(P9="","",P9-IF(Q9="",0,Q9)) | T9: =IF(Q9="","",Q9+IF(S9="",0,S9))
E10: IRRF | I10: CONTA TIM | L10: =IF(J10="","",J10+IF(K10="",0,K10)) | O10: PicPay Card | R10: =IF(P10="","",P10-IF(Q10="",0,Q10)) | T10: =IF(Q10="","",Q10+IF(S10="",0,S10))
E11: AUX.PRÉ.ESC | I11: CONTA CLARO | L11: =IF(J11="","",J11+IF(K11="",0,K11)) | O11: Itaú Card | R11: =IF(P11="","",P11-IF(Q11="",0,Q11)) | T11: =IF(Q11="","",Q11+IF(S11="",0,S11))
E12: Dízimo | I12: MAXÍDOMINI | L12: =IF(J12="","",J12+IF(K12="",0,K12)) | O12: CAIXA ELO | R12: =IF(P12="","",P12-IF(Q12="",0,Q12)) | T12: =IF(Q12="","",Q12+IF(S12="",0,S12))
I13: COSANPA/ÁGUA | L13: =IF(J13="","",J13+IF(K13="",0,K13)) | O13: Bradesco | R13: =IF(P13="","",P13-IF(Q13="",0,Q13)) | T13: =IF(Q13="","",Q13+IF(S13="",0,S13))
I14: ESCOLA SALMOM | L14: =IF(J14="","",J14+IF(K14="",0,K14)) | O14: RecargaPay | R14: =IF(P14="","",P14-IF(Q14="",0,Q14)) | T14: =IF(Q14="","",Q14+IF(S14="",0,S14))
I15: CORECON | L15: =IF(J15="","",J15+IF(K15="",0,K15)) | O15: BipaCard | R15: =IF(P15="","",P15-IF(Q15="",0,Q15)) | T15: =IF(Q15="","",Q15+IF(S15="",0,S15))
I16: Boticário | L16: =IF(J16="","",J16+IF(K16="",0,K16)) | O16: InfinitCard | R16: =IF(P16="","",P16-IF(Q16="",0,Q16)) | T16: =IF(Q16="","",Q16+IF(S16="",0,S16))
I17: Rodobens | L17: =IF(J17="","",J17+IF(K17="",0,K17)) | O17: Pagbank | R17: =IF(P17="","",P17-IF(Q17="",0,Q17)) | T17: =IF(Q17="","",Q17+IF(S17="",0,S17))
L18: =IF(J18="","",J18+IF(K18="",0,K18)) | O18: TonCard | R18: =IF(P18="","",P18-IF(Q18="",0,Q18)) | T18: =IF(Q18="","",Q18+IF(S18="",0,S18))
L19: =IF(J19="","",J19+IF(K19="",0,K19)) | R19: =IF(P19="","",P19-IF(Q19="",0,Q19)) | T19: =IF(Q19="","",Q19+IF(S19="",0,S19))
A20: RECEITA TOTAL | B20: =SUM(B4:B19) | E20: TOTAL DESCONTOS | F20: =SUM(F4:F19) | I20: TOTAL FIXAS (CET) | J20: =SUM(J4:J19) | K20: =SUM(K4:K19) | L20: =SUM(L4:L19) | O20: TOTAL CARTÕES | P20: =SUM(P4:P19) | Q20: =SUM(Q4:Q19) | R20: =SUM(R4:R19) | S20: =SUM(S4:S19) | T20: =SUM(T4:T19)
O21: ¹ SALDO = Fatura − Pago (valor não quitado = nova dívida do mês)
A22: ASSINATURAS ONLINE | F22: NOTAS / EMPRÉSTIMOS / CONSIGNADOS
A23: CARTÃO | B23: SERVIÇO | C23: VALOR | D23: DIA/SITUAÇÃO | F23: DESCRIÇÃO | G23: TAXA (am) | H23: TAXA (aa) | I23: OBS / SALDO
A24: NU | B24: GDRIVE SABRI | C24: 49.9 | D24: DIA 04 — CRÉDITO (NU) | F24: Consignado Nubank 1 | G24: 1.30% am | H24: 16.74% aa | I24: 73x
A25: NU | B25: CONTA TIM | C25: 42 | D25: DIA 15 — PG MANUAL | F25: Consignado Nubank 2 | G25: 1.57% am | H25: 21.85% aa | I25: 96x — saldo R$776,82
A26: SANTANDER SX | B26: PLANO CLARO | C26: 73.73 | D26: DIA 09 — PG MANUAL | F26: Fin. Habitação CAIXA | G26: 7% nominal
A27: NU | B27: YOUTUBE ST | C27: 53.9 | D27: DIA 25 — CRÉDITO (NU) | F27: Empréstimo Sabrina | I27: saldo R$2.503,46
A28: NU | B28: ICLOUD | C28: 5.9 | D28: DIA 01 — CRÉDITO (NU) | F28: Empréstimo Josy
B29: Serasa | C29: 23.9 | D29: DIA 17 —
B30: Kindle | C30: 24
A31: NU | B31: GPT | C31: 130 | D31: DIA 02 — CRÉDITO (NU)
A32: NU | B32: Copilot | C32: 109.9 | D32: DIA 04 — CRÉDITO (NU)
A33: NU | B33: WORD | C33: 0 | D33: Anual — CRÉDITO (NU)
A34: NU | B34: GDRIVE EWE | C34: 0 | D34: Ago/26 — CRÉDITO (NU)
B35: PDFVIEW | C35: 0 | D35: CRÉDITO (NU)
A36: TOTAL ASSINATURAS | C36: =SUM(C24:C35)
A38: CHEQUE ESPECIAL / DÍVIDAS FINANCEIRAS
A39: BANCO | B39: LIMITE | C39: USADO | D39: JUROS MÊS | E39: TAXA % aa | F39: DIAS | G39: SITUAÇÃO
A40: BB
A41: Santander
...

Sheet Jun
A1: ORÇAMENTO JUNHO 2026
A2: ▶ FONTES DE RECEITA | E2: ▶ DESCONTOS EM FOLHA | I2: ▶ DESPESAS FIXAS | O2: ▶ DESPESAS COM CARTÕES
A3: ORIGEM | B3: VALOR | C3: SITUAÇÃO | D3: DATA PG | E3: ORIGEM | F3: VALOR | G3: INFO | H3: OBS | I3: ORIGEM | J3: VALOR | K3: JUROS | L3: CET | M3: SITUAÇÃO | N3: DATA PG | O3: CARTÃO | P3: FATURA | Q3: PAGO | R3: SALDO¹ | S3: JUROS | T3: CET | U3: SITUAÇÃO | V3: DATA PG
A4: SALÁRIO | E4: Consignado V.Nbk | I4: HAPVIDA/SALMINHO | L4: =IF(J4="","",J4+IF(K4="",0,K4)) | O4: BB | R4: =IF(P4="","",P4-IF(Q4="",0,Q4)) | T4: =IF(Q4="","",Q4+IF(S4="",0,S4))
A5: Kalena OF/NET | E5: Caixa Habitação | I5: HAPVIDA/SABRINA | L5: =IF(J5="","",J5+IF(K5="",0,K5)) | O5: NU | R5: =IF(P5="","",P5-IF(Q5="",0,Q5)) | T5: =IF(Q5="","",Q5+IF(S5="",0,S5))
A6: ALUGUÉL | E6: Consignado BB | I6: HAP EWE E EFRA | L6: =IF(J6="","",J6+IF(K6="",0,K6)) | O6: Santander SX | R6: =IF(P6="","",P6-IF(Q6="",0,Q6)) | T6: =IF(Q6="","",Q6+IF(S6="",0,S6))
A7: Wagner | E7: Emp.Sal.BB | I7: CELPA ENERGIA | L7: =IF(J7="","",J7+IF(K7="",0,K7)) | O7: SELITE | R7: =IF(P7="","",P7-IF(Q7="",0,Q7)) | T7: =IF(Q7="","",Q7+IF(S7="",0,S7))
A8: Neto | E8: AUX.TRANSP | I8: SEATELECOM | L8: =IF(J8="","",J8+IF(K8="",0,K8)) | O8: Caixa Gold | R8: =IF(P8="","",P8-IF(Q8="",0,Q8)) | T8: =IF(Q8="","",Q8+IF(S8="",0,S8))
A9: UAB | E9: CONTRI.SOCIAL | I9: TX.ÁLAMO | L9: =IF(J9="","",J9+IF(K9="",0,K9)) | O9: Cartão MP | R9: =IF(P9="","",P9-IF(Q9="",0,Q9)) | T9: =IF(Q9="","",Q9+IF(S9="",0,S9))
E10: IRRF | I10: CONTA TIM | L10: =IF(J10="","",J10+IF(K10="",0,K10)) | O10: PicPay Card | R10: =IF(P10="","",P10-IF(Q10="",0,Q10)) | T10: =IF(Q10="","",Q10+IF(S10="",0,S10))
E11: AUX.PRÉ.ESC | I11: CONTA CLARO | L11: =IF(J11="","",J11+IF(K11="",0,K11)) | O11: Itaú Card | R11: =IF(P11="","",P11-IF(Q11="",0,Q11)) | T11: =IF(Q11="","",Q11+IF(S11="",0,S11))
E12: Dízimo | I12: MAXÍDOMINI | L12: =IF(J12="","",J12+IF(K12="",0,K12)) | O12: CAIXA ELO | R12: =IF(P12="","",P12-IF(Q12="",0,Q12)) | T12: =IF(Q12="","",Q12+IF(S12="",0,S12))
I13: COSANPA/ÁGUA | L13: =IF(J13="","",J13+IF(K13="",0,K13)) | O13: Bradesco | R13: =IF(P13="","",P13-IF(Q13="",0,Q13)) | T13: =IF(Q13="","",Q13+IF(S13="",0,S13))
I14: ESCOLA SALMOM | L14: =IF(J14="","",J14+IF(K14="",0,K14)) | O14: RecargaPay | R14: =IF(P14="","",P14-IF(Q14="",0,Q14)) | T14: =IF(Q14="","",Q14+IF(S14="",0,S14))
I15: CORECON | L15: =IF(J15="","",J15+IF(K15="",0,K15)) | O15: BipaCard | R15: =IF(P15="","",P15-IF(Q15="",0,Q15)) | T15: =IF(Q15="","",Q15+IF(S15="",0,S15))
I16: Boticário | L16: =IF(J16="","",J16+IF(K16="",0,K16)) | O16: InfinitCard | R16: =IF(P16="","",P16-IF(Q16="",0,Q16)) | T16: =IF(Q16="","",Q16+IF(S16="",0,S16))
I17: Rodobens | L17: =IF(J17="","",J17+IF(K17="",0,K17)) | O17: Pagbank | R17: =IF(P17="","",P17-IF(Q17="",0,Q17)) | T17: =IF(Q17="","",Q17+IF(S17="",0,S17))
L18: =IF(J18="","",J18+IF(K18="",0,K18)) | O18: TonCard | R18: =IF(P18="","",P18-IF(Q18="",0,Q18)) | T18: =IF(Q18="","",Q18+IF(S18="",0,S18))
L19: =IF(J19="","",J19+IF(K19="",0,K19)) | R19: =IF(P19="","",P19-IF(Q19="",0,Q19)) | T19: =IF(Q19="","",Q19+IF(S19="",0,S19))
A20: RECEITA TOTAL | B20: =SUM(B4:B19) | E20: TOTAL DESCONTOS | F20: =SUM(F4:F19) | I20: TOTAL FIXAS (CET) | J20: =SUM(J4:J19) | K20: =SUM(K4:K19) | L20: =SUM(L4:L19) | O20: TOTAL CARTÕES | P20: =SUM(P4:P19) | Q20: =SUM(Q4:Q19) | R20: =SUM(R4:R19) | S20: =SUM(S4:S19) | T20: =SUM(T4:T19)
O21: ¹ SALDO = Fatura − Pago (valor não quitado = nova dívida do mês)
A22: ASSINATURAS ONLINE | F22: NOTAS / EMPRÉSTIMOS / CONSIGNADOS
A23: CARTÃO | B23: SERVIÇO | C23: VALOR | D23: DIA/SITUAÇÃO | F23: DESCRIÇÃO | G23: TAXA (am) | H23: TAXA (aa) | I23: OBS / SALDO
A24: NU | B24: GDRIVE SABRI | C24: 49.9 | D24: DIA 04 — CRÉDITO (NU) | F24: Consignado Nubank 1 | G24: 1.30% am | H24: 16.74% aa | I24: 73x
A25: NU | B25: CONTA TIM | C25: 42 | D25: DIA 15 — PG MANUAL | F25: Consignado Nubank 2 | G25: 1.57% am | H25: 21.85% aa | I25: 96x — saldo R$776,82
A26: SANTANDER SX | B26: PLANO CLARO | C26: 73.73 | D26: DIA 09 — PG MANUAL | F26: Fin. Habitação CAIXA | G26: 7% nominal
A27: NU | B27: YOUTUBE ST | C27: 53.9 | D27: DIA 25 — CRÉDITO (NU) | F27: Empréstimo Sabrina | I27: saldo R$2.503,46
A28: NU | B28: ICLOUD | C28: 5.9 | D28: DIA 01 — CRÉDITO (NU) | F28: Empréstimo Josy
B29: Serasa | C29: 23.9 | D29: DIA 17 —
B30: Kindle | C30: 24
A31: NU | B31: GPT | C31: 130 | D31: DIA 02 — CRÉDITO (NU)
A32: NU | B32: Copilot | C32: 109.9 | D32: DIA 04 — CRÉDITO (NU)
A33: NU | B33: WORD | C33: 0 | D33: Anual — CRÉDITO (NU)
A34: NU | B34: GDRIVE EWE | C34: 0 | D34: Ago/26 — CRÉDITO (NU)
B35: PDFVIEW | C35: 0 | D35: CRÉDITO (NU)
A36: TOTAL ASSINATURAS | C36: =SUM(C24:C35)
A38: CHEQUE ESPECIAL / DÍVIDAS FINANCEIRAS
A39: BANCO | B39: LIMITE | C39: USADO | D39: JUROS MÊS | E39: TAXA % aa | F39: DIAS | G39: SITUAÇÃO
A40: BB
A41: Santander
...

Sheet Jul
A1: ORÇAMENTO JULHO 2026
A2: ▶ FONTES DE RECEITA | E2: ▶ DESCONTOS EM FOLHA | I2: ▶ DESPESAS FIXAS | O2: ▶ DESPESAS COM CARTÕES
A3: ORIGEM | B3: VALOR | C3: SITUAÇÃO | D3: DATA PG | E3: ORIGEM | F3: VALOR | G3: INFO | H3: OBS | I3: ORIGEM | J3: VALOR | K3: JUROS | L3: CET | M3: SITUAÇÃO | N3: DATA PG | O3: CARTÃO | P3: FATURA | Q3: PAGO | R3: SALDO¹ | S3: JUROS | T3: CET | U3: SITUAÇÃO | V3: DATA PG
A4: SALÁRIO | E4: Consignado V.Nbk | I4: HAPVIDA/SALMINHO | L4: =IF(J4="","",J4+IF(K4="",0,K4)) | O4: BB | R4: =IF(P4="","",P4-IF(Q4="",0,Q4)) | T4: =IF(Q4="","",Q4+IF(S4="",0,S4))
A5: Kalena OF/NET | E5: Caixa Habitação | I5: HAPVIDA/SABRINA | L5: =IF(J5="","",J5+IF(K5="",0,K5)) | O5: NU | R5: =IF(P5="","",P5-IF(Q5="",0,Q5)) | T5: =IF(Q5="","",Q5+IF(S5="",0,S5))
A6: ALUGUÉL | E6: Consignado BB | I6: HAP EWE E EFRA | L6: =IF(J6="","",J6+IF(K6="",0,K6)) | O6: Santander SX | R6: =IF(P6="","",P6-IF(Q6="",0,Q6)) | T6: =IF(Q6="","",Q6+IF(S6="",0,S6))
A7: Wagner | E7: Emp.Sal.BB | I7: CELPA ENERGIA | L7: =IF(J7="","",J7+IF(K7="",0,K7)) | O7: SELITE | R7: =IF(P7="","",P7-IF(Q7="",0,Q7)) | T7: =IF(Q7="","",Q7+IF(S7="",0,S7))
A8: Neto | E8: AUX.TRANSP | I8: SEATELECOM | L8: =IF(J8="","",J8+IF(K8="",0,K8)) | O8: Caixa Gold | R8: =IF(P8="","",P8-IF(Q8="",0,Q8)) | T8: =IF(Q8="","",Q8+IF(S8="",0,S8))
A9: UAB | E9: CONTRI.SOCIAL | I9: TX.ÁLAMO | L9: =IF(J9="","",J9+IF(K9="",0,K9)) | O9: Cartão MP | R9: =IF(P9="","",P9-IF(Q9="",0,Q9)) | T9: =IF(Q9="","",Q9+IF(S9="",0,S9))
E10: IRRF | I10: CONTA TIM | L10: =IF(J10="","",J10+IF(K10="",0,K10)) | O10: PicPay Card | R10: =IF(P10="","",P10-IF(Q10="",0,Q10)) | T10: =IF(Q10="","",Q10+IF(S10="",0,S10))
E11: AUX.PRÉ.ESC | I11: CONTA CLARO | L11: =IF(J11="","",J11+IF(K11="",0,K11)) | O11: Itaú Card | R11: =IF(P11="","",P11-IF(Q11="",0,Q11)) | T11: =IF(Q11="","",Q11+IF(S11="",0,S11))
E12: Dízimo | I12: MAXÍDOMINI | L12: =IF(J12="","",J12+IF(K12="",0,K12)) | O12: CAIXA ELO | R12: =IF(P12="","",P12-IF(Q12="",0,Q12)) | T12: =IF(Q12="","",Q12+IF(S12="",0,S12))
I13: COSANPA/ÁGUA | L13: =IF(J13="","",J13+IF(K13="",0,K13)) | O13: Bradesco | R13: =IF(P13="","",P13-IF(Q13="",0,Q13)) | T13: =IF(Q13="","",Q13+IF(S13="",0,S13))
I14: ESCOLA SALMOM | L14: =IF(J14="","",J14+IF(K14="",0,K14)) | O14: RecargaPay | R14: =IF(P14="","",P14-IF(Q14="",0,Q14)) | T14: =IF(Q14="","",Q14+IF(S14="",0,S14))
I15: CORECON | L15: =IF(J15="","",J15+IF(K15="",0,K15)) | O15: BipaCard | R15: =IF(P15="","",P15-IF(Q15="",0,Q15)) | T15: =IF(Q15="","",Q15+IF(S15="",0,S15))
I16: Boticário | L16: =IF(J16="","",J16+IF(K16="",0,K16)) | O16: InfinitCard | R16: =IF(P16="","",P16-IF(Q16="",0,Q16)) | T16: =IF(Q16="","",Q16+IF(S16="",0,S16))
I17: Rodobens | L17: =IF(J17="","",J17+IF(K17="",0,K17)) | O17: Pagbank | R17: =IF(P17="","",P17-IF(Q17="",0,Q17)) | T17: =IF(Q17="","",Q17+IF(S17="",0,S17))
L18: =IF(J18="","",J18+IF(K18="",0,K18)) | O18: TonCard | R18: =IF(P18="","",P18-IF(Q18="",0,Q18)) | T18: =IF(Q18="","",Q18+IF(S18="",0,S18))
L19: =IF(J19="","",J19+IF(K19="",0,K19)) | R19: =IF(P19="","",P19-IF(Q19="",0,Q19)) | T19: =IF(Q19="","",Q19+IF(S19="",0,S19))
A20: RECEITA TOTAL | B20: =SUM(B4:B19) | E20: TOTAL DESCONTOS | F20: =SUM(F4:F19) | I20: TOTAL FIXAS (CET) | J20: =SUM(J4:J19) | K20: =SUM(K4:K19) | L20: =SUM(L4:L19) | O20: TOTAL CARTÕES | P20: =SUM(P4:P19) | Q20: =SUM(Q4:Q19) | R20: =SUM(R4:R19) | S20: =SUM(S4:S19) | T20: =SUM(T4:T19)
O21: ¹ SALDO = Fatura − Pago (valor não quitado = nova dívida do mês)
A22: ASSINATURAS ONLINE | F22: NOTAS / EMPRÉSTIMOS / CONSIGNADOS
A23: CARTÃO | B23: SERVIÇO | C23: VALOR | D23: DIA/SITUAÇÃO | F23: DESCRIÇÃO | G23: TAXA (am) | H23: TAXA (aa) | I23: OBS / SALDO
A24: NU | B24: GDRIVE SABRI | C24: 49.9 | D24: DIA 04 — CRÉDITO (NU) | F24: Consignado Nubank 1 | G24: 1.30% am | H24: 16.74% aa | I24: 73x
A25: NU | B25: CONTA TIM | C25: 42 | D25: DIA 15 — PG MANUAL | F25: Consignado Nubank 2 | G25: 1.57% am | H25: 21.85% aa | I25: 96x — saldo R$776,82
A26: SANTANDER SX | B26: PLANO CLARO | C26: 73.73 | D26: DIA 09 — PG MANUAL | F26: Fin. Habitação CAIXA | G26: 7% nominal
A27: NU | B27: YOUTUBE ST | C27: 53.9 | D27: DIA 25 — CRÉDITO (NU) | F27: Empréstimo Sabrina | I27: saldo R$2.503,46
A28: NU | B28: ICLOUD | C28: 5.9 | D28: DIA 01 — CRÉDITO (NU) | F28: Empréstimo Josy
B29: Serasa | C29: 23.9 | D29: DIA 17 —
B30: Kindle | C30: 24
A31: NU | B31: GPT | C31: 130 | D31: DIA 02 — CRÉDITO (NU)
A32: NU | B32: Copilot | C32: 109.9 | D32: DIA 04 — CRÉDITO (NU)
A33: NU | B33: WORD | C33: 0 | D33: Anual — CRÉDITO (NU)
A34: NU | B34: GDRIVE EWE | C34: 0 | D34: Ago/26 — CRÉDITO (NU)
B35: PDFVIEW | C35: 0 | D35: CRÉDITO (NU)
A36: TOTAL ASSINATURAS | C36: =SUM(C24:C35)
A38: CHEQUE ESPECIAL / DÍVIDAS FINANCEIRAS
A39: BANCO | B39: LIMITE | C39: USADO | D39: JUROS MÊS | E39: TAXA % aa | F39: DIAS | G39: SITUAÇÃO
A40: BB
A41: Santander
...

Sheet Ago
A1: ORÇAMENTO AGOSTO 2026
A2: ▶ FONTES DE RECEITA | E2: ▶ DESCONTOS EM FOLHA | I2: ▶ DESPESAS FIXAS | O2: ▶ DESPESAS COM CARTÕES
A3: ORIGEM | B3: VALOR | C3: SITUAÇÃO | D3: DATA PG | E3: ORIGEM | F3: VALOR | G3: INFO | H3: OBS | I3: ORIGEM | J3: VALOR | K3: JUROS | L3: CET | M3: SITUAÇÃO | N3: DATA PG | O3: CARTÃO | P3: FATURA | Q3: PAGO | R3: SALDO¹ | S3: JUROS | T3: CET | U3: SITUAÇÃO | V3: DATA PG
A4: SALÁRIO | E4: Consignado V.Nbk | I4: HAPVIDA/SALMINHO | L4: =IF(J4="","",J4+IF(K4="",0,K4)) | O4: BB | R4: =IF(P4="","",P4-IF(Q4="",0,Q4)) | T4: =IF(Q4="","",Q4+IF(S4="",0,S4))
A5: Kalena OF/NET | E5: Caixa Habitação | I5: HAPVIDA/SABRINA | L5: =IF(J5="","",J5+IF(K5="",0,K5)) | O5: NU | R5: =IF(P5="","",P5-IF(Q5="",0,Q5)) | T5: =IF(Q5="","",Q5+IF(S5="",0,S5))
A6: ALUGUÉL | E6: Consignado BB | I6: HAP EWE E EFRA | L6: =IF(J6="","",J6+IF(K6="",0,K6)) | O6: Santander SX | R6: =IF(P6="","",P6-IF(Q6="",0,Q6)) | T6: =IF(Q6="","",Q6+IF(S6="",0,S6))
A7: Wagner | E7: Emp.Sal.BB | I7: CELPA ENERGIA | L7: =IF(J7="","",J7+IF(K7="",0,K7)) | O7: SELITE | R7: =IF(P7="","",P7-IF(Q7="",0,Q7)) | T7: =IF(Q7="","",Q7+IF(S7="",0,S7))
A8: Neto | E8: AUX.TRANSP | I8: SEATELECOM | L8: =IF(J8="","",J8+IF(K8="",0,K8)) | O8: Caixa Gold | R8: =IF(P8="","",P8-IF(Q8="",0,Q8)) | T8: =IF(Q8="","",Q8+IF(S8="",0,S8))
A9: UAB | E9: CONTRI.SOCIAL | I9: TX.ÁLAMO | L9: =IF(J9="","",J9+IF(K9="",0,K9)) | O9: Cartão MP | R9: =IF(P9="","",P9-IF(Q9="",0,Q9)) | T9: =IF(Q9="","",Q9+IF(S9="",0,S9))
E10: IRRF | I10: CONTA TIM | L10: =IF(J10="","",J10+IF(K10="",0,K10)) | O10: PicPay Card | R10: =IF(P10="","",P10-IF(Q10="",0,Q10)) | T10: =IF(Q10="","",Q10+IF(S10="",0,S10))
E11: AUX.PRÉ.ESC | I11: CONTA CLARO | L11: =IF(J11="","",J11+IF(K11="",0,K11)) | O11: Itaú Card | R11: =IF(P11="","",P11-IF(Q11="",0,Q11)) | T11: =IF(Q11="","",Q11+IF(S11="",0,S11))
E12: Dízimo | I12: MAXÍDOMINI | L12: =IF(J12="","",J12+IF(K12="",0,K12)) | O12: CAIXA ELO | R12: =IF(P12="","",P12-IF(Q12="",0,Q12)) | T12: =IF(Q12="","",Q12+IF(S12="",0,S12))
I13: COSANPA/ÁGUA | L13: =IF(J13="","",J13+IF(K13="",0,K13)) | O13: Bradesco | R13: =IF(P13="","",P13-IF(Q13="",0,Q13)) | T13: =IF(Q13="","",Q13+IF(S13="",0,S13))
I14: ESCOLA SALMOM | L14: =IF(J14="","",J14+IF(K14="",0,K14)) | O14: RecargaPay | R14: =IF(P14="","",P14-IF(Q14="",0,Q14)) | T14: =IF(Q14="","",Q14+IF(S14="",0,S14))
I15: CORECON | L15: =IF(J15="","",J15+IF(K15="",0,K15)) | O15: BipaCard | R15: =IF(P15="","",P15-IF(Q15="",0,Q15)) | T15: =IF(Q15="","",Q15+IF(S15="",0,S15))
I16: Boticário | L16: =IF(J16="","",J16+IF(K16="",0,K16)) | O16: InfinitCard | R16: =IF(P16="","",P16-IF(Q16="",0,Q16)) | T16: =IF(Q16="","",Q16+IF(S16="",0,S16))
I17: Rodobens | L17: =IF(J17="","",J17+IF(K17="",0,K17)) | O17: Pagbank | R17: =IF(P17="","",P17-IF(Q17="",0,Q17)) | T17: =IF(Q17="","",Q17+IF(S17="",0,S17))
L18: =IF(J18="","",J18+IF(K18="",0,K18)) | O18: TonCard | R18: =IF(P18="","",P18-IF(Q18="",0,Q18)) | T18: =IF(Q18="","",Q18+IF(S18="",0,S18))
L19: =IF(J19="","",J19+IF(K19="",0,K19)) | R19: =IF(P19="","",P19-IF(Q19="",0,Q19)) | T19: =IF(Q19="","",Q19+IF(S19="",0,S19))
A20: RECEITA TOTAL | B20: =SUM(B4:B19) | E20: TOTAL DESCONTOS | F20: =SUM(F4:F19) | I20: TOTAL FIXAS (CET) | J20: =SUM(J4:J19) | K20: =SUM(K4:K19) | L20: =SUM(L4:L19) | O20: TOTAL CARTÕES | P20: =SUM(P4:P19) | Q20: =SUM(Q4:Q19) | R20: =SUM(R4:R19) | S20: =SUM(S4:S19) | T20: =SUM(T4:T19)
O21: ¹ SALDO = Fatura − Pago (valor não quitado = nova dívida do mês)
A22: ASSINATURAS ONLINE | F22: NOTAS / EMPRÉSTIMOS / CONSIGNADOS
A23: CARTÃO | B23: SERVIÇO | C23: VALOR | D23: DIA/SITUAÇÃO | F23: DESCRIÇÃO | G23: TAXA (am) | H23: TAXA (aa) | I23: OBS / SALDO
A24: NU | B24: GDRIVE SABRI | C24: 49.9 | D24: DIA 04 — CRÉDITO (NU) | F24: Consignado Nubank 1 | G24: 1.30% am | H24: 16.74% aa | I24: 73x
A25: NU | B25: CONTA TIM | C25: 42 | D25: DIA 15 — PG MANUAL | F25: Consignado Nubank 2 | G25: 1.57% am | H25: 21.85% aa | I25: 96x — saldo R$776,82
A26: SANTANDER SX | B26: PLANO CLARO | C26: 73.73 | D26: DIA 09 — PG MANUAL | F26: Fin. Habitação CAIXA | G26: 7% nominal
A27: NU | B27: YOUTUBE ST | C27: 53.9 | D27: DIA 25 — CRÉDITO (NU) | F27: Empréstimo Sabrina | I27: saldo R$2.503,46
A28: NU | B28: ICLOUD | C28: 5.9 | D28: DIA 01 — CRÉDITO (NU) | F28: Empréstimo Josy
B29: Serasa | C29: 23.9 | D29: DIA 17 —
B30: Kindle | C30: 24
A31: NU | B31: GPT | C31: 130 | D31: DIA 02 — CRÉDITO (NU)
A32: NU | B32: Copilot | C32: 109.9 | D32: DIA 04 — CRÉDITO (NU)
A33: NU | B33: WORD | C33: 0 | D33: Anual — CRÉDITO (NU)
A34: NU | B34: GDRIVE EWE | C34: 0 | D34: Ago/26 — CRÉDITO (NU)
B35: PDFVIEW | C35: 0 | D35: CRÉDITO (NU)
A36: TOTAL ASSINATURAS | C36: =SUM(C24:C35)
A38: CHEQUE ESPECIAL / DÍVIDAS FINANCEIRAS
A39: BANCO | B39: LIMITE | C39: USADO | D39: JUROS MÊS | E39: TAXA % aa | F39: DIAS | G39: SITUAÇÃO
A40: BB
A41: Santander
...

Sheet Set
A1: ORÇAMENTO SETEMBRO 2026
A2: ▶ FONTES DE RECEITA | E2: ▶ DESCONTOS EM FOLHA | I2: ▶ DESPESAS FIXAS | O2: ▶ DESPESAS COM CARTÕES
A3: ORIGEM | B3: VALOR | C3: SITUAÇÃO | D3: DATA PG | E3: ORIGEM | F3: VALOR | G3: INFO | H3: OBS | I3: ORIGEM | J3: VALOR | K3: JUROS | L3: CET | M3: SITUAÇÃO | N3: DATA PG | O3: CARTÃO | P3: FATURA | Q3: PAGO | R3: SALDO¹ | S3: JUROS | T3: CET | U3: SITUAÇÃO | V3: DATA PG
A4: SALÁRIO | E4: Consignado V.Nbk | I4: HAPVIDA/SALMINHO | L4: =IF(J4="","",J4+IF(K4="",0,K4)) | O4: BB | R4: =IF(P4="","",P4-IF(Q4="",0,Q4)) | T4: =IF(Q4="","",Q4+IF(S4="",0,S4))
A5: Kalena OF/NET | E5: Caixa Habitação | I5: HAPVIDA/SABRINA | L5: =IF(J5="","",J5+IF(K5="",0,K5)) | O5: NU | R5: =IF(P5="","",P5-IF(Q5="",0,Q5)) | T5: =IF(Q5="","",Q5+IF(S5="",0,S5))
A6: ALUGUÉL | E6: Consignado BB | I6: HAP EWE E EFRA | L6: =IF(J6="","",J6+IF(K6="",0,K6)) | O6: Santander SX | R6: =IF(P6="","",P6-IF(Q6="",0,Q6)) | T6: =IF(Q6="","",Q6+IF(S6="",0,S6))
A7: Wagner | E7: Emp.Sal.BB | I7: CELPA ENERGIA | L7: =IF(J7="","",J7+IF(K7="",0,K7)) | O7: SELITE | R7: =IF(P7="","",P7-IF(Q7="",0,Q7)) | T7: =IF(Q7="","",Q7+IF(S7="",0,S7))
A8: Neto | E8: AUX.TRANSP | I8: SEATELECOM | L8: =IF(J8="","",J8+IF(K8="",0,K8)) | O8: Caixa Gold | R8: =IF(P8="","",P8-IF(Q8="",0,Q8)) | T8: =IF(Q8="","",Q8+IF(S8="",0,S8))
A9: UAB | E9: CONTRI.SOCIAL | I9: TX.ÁLAMO | L9: =IF(J9="","",J9+IF(K9="",0,K9)) | O9: Cartão MP | R9: =IF(P9="","",P9-IF(Q9="",0,Q9)) | T9: =IF(Q9="","",Q9+IF(S9="",0,S9))
E10: IRRF | I10: CONTA TIM | L10: =IF(J10="","",J10+IF(K10="",0,K10)) | O10: PicPay Card | R10: =IF(P10="","",P10-IF(Q10="",0,Q10)) | T10: =IF(Q10="","",Q10+IF(S10="",0,S10))
E11: AUX.PRÉ.ESC | I11: CONTA CLARO | L11: =IF(J11="","",J11+IF(K11="",0,K11)) | O11: Itaú Card | R11: =IF(P11="","",P11-IF(Q11="",0,Q11)) | T11: =IF(Q11="","",Q11+IF(S11="",0,S11))
E12: Dízimo | I12: MAXÍDOMINI | L12: =IF(J12="","",J12+IF(K12="",0,K12)) | O12: CAIXA ELO | R12: =IF(P12="","",P12-IF(Q12="",0,Q12)) | T12: =IF(Q12="","",Q12+IF(S12="",0,S12))
I13: COSANPA/ÁGUA | L13: =IF(J13="","",J13+IF(K13="",0,K13)) | O13: Bradesco | R13: =IF(P13="","",P13-IF(Q13="",0,Q13)) | T13: =IF(Q13="","",Q13+IF(S13="",0,S13))
I14: ESCOLA SALMOM | L14: =IF(J14="","",J14+IF(K14="",0,K14)) | O14: RecargaPay | R14: =IF(P14="","",P14-IF(Q14="",0,Q14)) | T14: =IF(Q14="","",Q14+IF(S14="",0,S14))
I15: CORECON | L15: =IF(J15="","",J15+IF(K15="",0,K15)) | O15: BipaCard | R15: =IF(P15="","",P15-IF(Q15="",0,Q15)) | T15: =IF(Q15="","",Q15+IF(S15="",0,S15))
I16: Boticário | L16: =IF(J16="","",J16+IF(K16="",0,K16)) | O16: InfinitCard | R16: =IF(P16="","",P16-IF(Q16="",0,Q16)) | T16: =IF(Q16="","",Q16+IF(S16="",0,S16))
I17: Rodobens | L17: =IF(J17="","",J17+IF(K17="",0,K17)) | O17: Pagbank | R17: =IF(P17="","",P17-IF(Q17="",0,Q17)) | T17: =IF(Q17="","",Q17+IF(S17="",0,S17))
L18: =IF(J18="","",J18+IF(K18="",0,K18)) | O18: TonCard | R18: =IF(P18="","",P18-IF(Q18="",0,Q18)) | T18: =IF(Q18="","",Q18+IF(S18="",0,S18))
L19: =IF(J19="","",J19+IF(K19="",0,K19)) | R19: =IF(P19="","",P19-IF(Q19="",0,Q19)) | T19: =IF(Q19="","",Q19+IF(S19="",0,S19))
A20: RECEITA TOTAL | B20: =SUM(B4:B19) | E20: TOTAL DESCONTOS | F20: =SUM(F4:F19) | I20: TOTAL FIXAS (CET) | J20: =SUM(J4:J19) | K20: =SUM(K4:K19) | L20: =SUM(L4:L19) | O20: TOTAL CARTÕES | P20: =SUM(P4:P19) | Q20: =SUM(Q4:Q19) | R20: =SUM(R4:R19) | S20: =SUM(S4:S19) | T20: =SUM(T4:T19)
O21: ¹ SALDO = Fatura − Pago (valor não quitado = nova dívida do mês)
A22: ASSINATURAS ONLINE | F22: NOTAS / EMPRÉSTIMOS / CONSIGNADOS
A23: CARTÃO | B23: SERVIÇO | C23: VALOR | D23: DIA/SITUAÇÃO | F23: DESCRIÇÃO | G23: TAXA (am) | H23: TAXA (aa) | I23: OBS / SALDO
A24: NU | B24: GDRIVE SABRI | C24: 49.9 | D24: DIA 04 — CRÉDITO (NU) | F24: Consignado Nubank 1 | G24: 1.30% am | H24: 16.74% aa | I24: 73x
A25: NU | B25: CONTA TIM | C25: 42 | D25: DIA 15 — PG MANUAL | F25: Consignado Nubank 2 | G25: 1.57% am | H25: 21.85% aa | I25: 96x — saldo R$776,82
A26: SANTANDER SX | B26: PLANO CLARO | C26: 73.73 | D26: DIA 09 — PG MANUAL | F26: Fin. Habitação CAIXA | G26: 7% nominal
A27: NU | B27: YOUTUBE ST | C27: 53.9 | D27: DIA 25 — CRÉDITO (NU) | F27: Empréstimo Sabrina | I27: saldo R$2.503,46
A28: NU | B28: ICLOUD | C28: 5.9 | D28: DIA 01 — CRÉDITO (NU) | F28: Empréstimo Josy
B29: Serasa | C29: 23.9 | D29: DIA 17 —
B30: Kindle | C30: 24
A31: NU | B31: GPT | C31: 130 | D31: DIA 02 — CRÉDITO (NU)
A32: NU | B32: Copilot | C32: 109.9 | D32: DIA 04 — CRÉDITO (NU)
A33: NU | B33: WORD | C33: 0 | D33: Anual — CRÉDITO (NU)
A34: NU | B34: GDRIVE EWE | C34: 0 | D34: Ago/26 — CRÉDITO (NU)
B35: PDFVIEW | C35: 0 | D35: CRÉDITO (NU)
A36: TOTAL ASSINATURAS | C36: =SUM(C24:C35)
A38: CHEQUE ESPECIAL / DÍVIDAS FINANCEIRAS
A39: BANCO | B39: LIMITE | C39: USADO | D39: JUROS MÊS | E39: TAXA % aa | F39: DIAS | G39: SITUAÇÃO
A40: BB
A41: Santander
...

Sheet Out
A1: ORÇAMENTO OUTUBRO 2026
A2: ▶ FONTES DE RECEITA | E2: ▶ DESCONTOS EM FOLHA | I2: ▶ DESPESAS FIXAS | O2: ▶ DESPESAS COM CARTÕES
A3: ORIGEM | B3: VALOR | C3: SITUAÇÃO | D3: DATA PG | E3: ORIGEM | F3: VALOR | G3: INFO | H3: OBS | I3: ORIGEM | J3: VALOR | K3: JUROS | L3: CET | M3: SITUAÇÃO | N3: DATA PG | O3: CARTÃO | P3: FATURA | Q3: PAGO | R3: SALDO¹ | S3: JUROS | T3: CET | U3: SITUAÇÃO | V3: DATA PG
A4: SALÁRIO | E4: Consignado V.Nbk | I4: HAPVIDA/SALMINHO | L4: =IF(J4="","",J4+IF(K4="",0,K4)) | O4: BB | R4: =IF(P4="","",P4-IF(Q4="",0,Q4)) | T4: =IF(Q4="","",Q4+IF(S4="",0,S4))
A5: Kalena OF/NET | E5: Caixa Habitação | I5: HAPVIDA/SABRINA | L5: =IF(J5="","",J5+IF(K5="",0,K5)) | O5: NU | R5: =IF(P5="","",P5-IF(Q5="",0,Q5)) | T5: =IF(Q5="","",Q5+IF(S5="",0,S5))
A6: ALUGUÉL | E6: Consignado BB | I6: HAP EWE E EFRA | L6: =IF(J6="","",J6+IF(K6="",0,K6)) | O6: Santander SX | R6: =IF(P6="","",P6-IF(Q6="",0,Q6)) | T6: =IF(Q6="","",Q6+IF(S6="",0,S6))
A7: Wagner | E7: Emp.Sal.BB | I7: CELPA ENERGIA | L7: =IF(J7="","",J7+IF(K7="",0,K7)) | O7: SELITE | R7: =IF(P7="","",P7-IF(Q7="",0,Q7)) | T7: =IF(Q7="","",Q7+IF(S7="",0,S7))
A8: Neto | E8: AUX.TRANSP | I8: SEATELECOM | L8: =IF(J8="","",J8+IF(K8="",0,K8)) | O8: Caixa Gold | R8: =IF(P8="","",P8-IF(Q8="",0,Q8)) | T8: =IF(Q8="","",Q8+IF(S8="",0,S8))
A9: UAB | E9: CONTRI.SOCIAL | I9: TX.ÁLAMO | L9: =IF(J9="","",J9+IF(K9="",0,K9)) | O9: Cartão MP | R9: =IF(P9="","",P9-IF(Q9="",0,Q9)) | T9: =IF(Q9="","",Q9+IF(S9="",0,S9))
E10: IRRF | I10: CONTA TIM | L10: =IF(J10="","",J10+IF(K10="",0,K10)) | O10: PicPay Card | R10: =IF(P10="","",P10-IF(Q10="",0,Q10)) | T10: =IF(Q10="","",Q10+IF(S10="",0,S10))
E11: AUX.PRÉ.ESC | I11: CONTA CLARO | L11: =IF(J11="","",J11+IF(K11="",0,K11)) | O11: Itaú Card | R11: =IF(P11="","",P11-IF(Q11="",0,Q11)) | T11: =IF(Q11="","",Q11+IF(S11="",0,S11))
E12: Dízimo | I12: MAXÍDOMINI | L12: =IF(J12="","",J12+IF(K12="",0,K12)) | O12: CAIXA ELO | R12: =IF(P12="","",P12-IF(Q12="",0,Q12)) | T12: =IF(Q12="","",Q12+IF(S12="",0,S12))
I13: COSANPA/ÁGUA | L13: =IF(J13="","",J13+IF(K13="",0,K13)) | O13: Bradesco | R13: =IF(P13="","",P13-IF(Q13="",0,Q13)) | T13: =IF(Q13="","",Q13+IF(S13="",0,S13))
I14: ESCOLA SALMOM | L14: =IF(J14="","",J14+IF(K14="",0,K14)) | O14: RecargaPay | R14: =IF(P14="","",P14-IF(Q14="",0,Q14)) | T14: =IF(Q14="","",Q14+IF(S14="",0,S14))
I15: CORECON | L15: =IF(J15="","",J15+IF(K15="",0,K15)) | O15: BipaCard | R15: =IF(P15="","",P15-IF(Q15="",0,Q15)) | T15: =IF(Q15="","",Q15+IF(S15="",0,S15))
I16: Boticário | L16: =IF(J16="","",J16+IF(K16="",0,K16)) | O16: InfinitCard | R16: =IF(P16="","",P16-IF(Q16="",0,Q16)) | T16: =IF(Q16="","",Q16+IF(S16="",0,S16))
I17: Rodobens | L17: =IF(J17="","",J17+IF(K17="",0,K17)) | O17: Pagbank | R17: =IF(P17="","",P17-IF(Q17="",0,Q17)) | T17: =IF(Q17="","",Q17+IF(S17="",0,S17))
L18: =IF(J18="","",J18+IF(K18="",0,K18)) | O18: TonCard | R18: =IF(P18="","",P18-IF(Q18="",0,Q18)) | T18: =IF(Q18="","",Q18+IF(S18="",0,S18))
L19: =IF(J19="","",J19+IF(K19="",0,K19)) | R19: =IF(P19="","",P19-IF(Q19="",0,Q19)) | T19: =IF(Q19="","",Q19+IF(S19="",0,S19))
A20: RECEITA TOTAL | B20: =SUM(B4:B19) | E20: TOTAL DESCONTOS | F20: =SUM(F4:F19) | I20: TOTAL FIXAS (CET) | J20: =SUM(J4:J19) | K20: =SUM(K4:K19) | L20: =SUM(L4:L19) | O20: TOTAL CARTÕES | P20: =SUM(P4:P19) | Q20: =SUM(Q4:Q19) | R20: =SUM(R4:R19) | S20: =SUM(S4:S19) | T20: =SUM(T4:T19)
O21: ¹ SALDO = Fatura − Pago (valor não quitado = nova dívida do mês)
A22: ASSINATURAS ONLINE | F22: NOTAS / EMPRÉSTIMOS / CONSIGNADOS
A23: CARTÃO | B23: SERVIÇO | C23: VALOR | D23: DIA/SITUAÇÃO | F23: DESCRIÇÃO | G23: TAXA (am) | H23: TAXA (aa) | I23: OBS / SALDO
A24: NU | B24: GDRIVE SABRI | C24: 49.9 | D24: DIA 04 — CRÉDITO (NU) | F24: Consignado Nubank 1 | G24: 1.30% am | H24: 16.74% aa | I24: 73x
A25: NU | B25: CONTA TIM | C25: 42 | D25: DIA 15 — PG MANUAL | F25: Consignado Nubank 2 | G25: 1.57% am | H25: 21.85% aa | I25: 96x — saldo R$776,82
A26: SANTANDER SX | B26: PLANO CLARO | C26: 73.73 | D26: DIA 09 — PG MANUAL | F26: Fin. Habitação CAIXA | G26: 7% nominal
A27: NU | B27: YOUTUBE ST | C27: 53.9 | D27: DIA 25 — CRÉDITO (NU) | F27: Empréstimo Sabrina | I27: saldo R$2.503,46
A28: NU | B28: ICLOUD | C28: 5.9 | D28: DIA 01 — CRÉDITO (NU) | F28: Empréstimo Josy
B29: Serasa | C29: 23.9 | D29: DIA 17 —
B30: Kindle | C30: 24
A31: NU | B31: GPT | C31: 130 | D31: DIA 02 — CRÉDITO (NU)
A32: NU | B32: Copilot | C32: 109.9 | D32: DIA 04 — CRÉDITO (NU)
A33: NU | B33: WORD | C33: 0 | D33: Anual — CRÉDITO (NU)
A34: NU | B34: GDRIVE EWE | C34: 0 | D34: Ago/26 — CRÉDITO (NU)
B35: PDFVIEW | C35: 0 | D35: CRÉDITO (NU)
A36: TOTAL ASSINATURAS | C36: =SUM(C24:C35)
A38: CHEQUE ESPECIAL / DÍVIDAS FINANCEIRAS
A39: BANCO | B39: LIMITE | C39: USADO | D39: JUROS MÊS | E39: TAXA % aa | F39: DIAS | G39: SITUAÇÃO
A40: BB
A41: Santander
...

Sheet Nov
A1: ORÇAMENTO NOVEMBRO 2026
A2: ▶ FONTES DE RECEITA | E2: ▶ DESCONTOS EM FOLHA | I2: ▶ DESPESAS FIXAS | O2: ▶ DESPESAS COM CARTÕES
A3: ORIGEM | B3: VALOR | C3: SITUAÇÃO | D3: DATA PG | E3: ORIGEM | F3: VALOR | G3: INFO | H3: OBS | I3: ORIGEM | J3: VALOR | K3: JUROS | L3: CET | M3: SITUAÇÃO | N3: DATA PG | O3: CARTÃO | P3: FATURA | Q3: PAGO | R3: SALDO¹ | S3: JUROS | T3: CET | U3: SITUAÇÃO | V3: DATA PG
A4: SALÁRIO | E4: Consignado V.Nbk | I4: HAPVIDA/SALMINHO | L4: =IF(J4="","",J4+IF(K4="",0,K4)) | O4: BB | R4: =IF(P4="","",P4-IF(Q4="",0,Q4)) | T4: =IF(Q4="","",Q4+IF(S4="",0,S4))
A5: Kalena OF/NET | E5: Caixa Habitação | I5: HAPVIDA/SABRINA | L5: =IF(J5="","",J5+IF(K5="",0,K5)) | O5: NU | R5: =IF(P5="","",P5-IF(Q5="",0,Q5)) | T5: =IF(Q5="","",Q5+IF(S5="",0,S5))
A6: ALUGUÉL | E6: Consignado BB | I6: HAP EWE E EFRA | L6: =IF(J6="","",J6+IF(K6="",0,K6)) | O6: Santander SX | R6: =IF(P6="","",P6-IF(Q6="",0,Q6)) | T6: =IF(Q6="","",Q6+IF(S6="",0,S6))
A7: Wagner | E7: Emp.Sal.BB | I7: CELPA ENERGIA | L7: =IF(J7="","",J7+IF(K7="",0,K7)) | O7: SELITE | R7: =IF(P7="","",P7-IF(Q7="",0,Q7)) | T7: =IF(Q7="","",Q7+IF(S7="",0,S7))
A8: Neto | E8: AUX.TRANSP | I8: SEATELECOM | L8: =IF(J8="","",J8+IF(K8="",0,K8)) | O8: Caixa Gold | R8: =IF(P8="","",P8-IF(Q8="",0,Q8)) | T8: =IF(Q8="","",Q8+IF(S8="",0,S8))
A9: UAB | E9: CONTRI.SOCIAL | I9: TX.ÁLAMO | L9: =IF(J9="","",J9+IF(K9="",0,K9)) | O9: Cartão MP | R9: =IF(P9="","",P9-IF(Q9="",0,Q9)) | T9: =IF(Q9="","",Q9+IF(S9="",0,S9))
E10: IRRF | I10: CONTA TIM | L10: =IF(J10="","",J10+IF(K10="",0,K10)) | O10: PicPay Card | R10: =IF(P10="","",P10-IF(Q10="",0,Q10)) | T10: =IF(Q10="","",Q10+IF(S10="",0,S10))
E11: AUX.PRÉ.ESC | I11: CONTA CLARO | L11: =IF(J11="","",J11+IF(K11="",0,K11)) | O11: Itaú Card | R11: =IF(P11="","",P11-IF(Q11="",0,Q11)) | T11: =IF(Q11="","",Q11+IF(S11="",0,S11))
E12: Dízimo | I12: MAXÍDOMINI | L12: =IF(J12="","",J12+IF(K12="",0,K12)) | O12: CAIXA ELO | R12: =IF(P12="","",P12-IF(Q12="",0,Q12)) | T12: =IF(Q12="","",Q12+IF(S12="",0,S12))
I13: COSANPA/ÁGUA | L13: =IF(J13="","",J13+IF(K13="",0,K13)) | O13: Bradesco | R13: =IF(P13="","",P13-IF(Q13="",0,Q13)) | T13: =IF(Q13="","",Q13+IF(S13="",0,S13))
I14: ESCOLA SALMOM | L14: =IF(J14="","",J14+IF(K14="",0,K14)) | O14: RecargaPay | R14: =IF(P14="","",P14-IF(Q14="",0,Q14)) | T14: =IF(Q14="","",Q14+IF(S14="",0,S14))
I15: CORECON | L15: =IF(J15="","",J15+IF(K15="",0,K15)) | O15: BipaCard | R15: =IF(P15="","",P15-IF(Q15="",0,Q15)) | T15: =IF(Q15="","",Q15+IF(S15="",0,S15))
I16: Boticário | L16: =IF(J16="","",J16+IF(K16="",0,K16)) | O16: InfinitCard | R16: =IF(P16="","",P16-IF(Q16="",0,Q16)) | T16: =IF(Q16="","",Q16+IF(S16="",0,S16))
I17: Rodobens | L17: =IF(J17="","",J17+IF(K17="",0,K17)) | O17: Pagbank | R17: =IF(P17="","",P17-IF(Q17="",0,Q17)) | T17: =IF(Q17="","",Q17+IF(S17="",0,S17))
L18: =IF(J18="","",J18+IF(K18="",0,K18)) | O18: TonCard | R18: =IF(P18="","",P18-IF(Q18="",0,Q18)) | T18: =IF(Q18="","",Q18+IF(S18="",0,S18))
L19: =IF(J19="","",J19+IF(K19="",0,K19)) | R19: =IF(P19="","",P19-IF(Q19="",0,Q19)) | T19: =IF(Q19="","",Q19+IF(S19="",0,S19))
A20: RECEITA TOTAL | B20: =SUM(B4:B19) | E20: TOTAL DESCONTOS | F20: =SUM(F4:F19) | I20: TOTAL FIXAS (CET) | J20: =SUM(J4:J19) | K20: =SUM(K4:K19) | L20: =SUM(L4:L19) | O20: TOTAL CARTÕES | P20: =SUM(P4:P19) | Q20: =SUM(Q4:Q19) | R20: =SUM(R4:R19) | S20: =SUM(S4:S19) | T20: =SUM(T4:T19)
O21: ¹ SALDO = Fatura − Pago (valor não quitado = nova dívida do mês)
A22: ASSINATURAS ONLINE | F22: NOTAS / EMPRÉSTIMOS / CONSIGNADOS
A23: CARTÃO | B23: SERVIÇO | C23: VALOR | D23: DIA/SITUAÇÃO | F23: DESCRIÇÃO | G23: TAXA (am) | H23: TAXA (aa) | I23: OBS / SALDO
A24: NU | B24: GDRIVE SABRI | C24: 49.9 | D24: DIA 04 — CRÉDITO (NU) | F24: Consignado Nubank 1 | G24: 1.30% am | H24: 16.74% aa | I24: 73x
A25: NU | B25: CONTA TIM | C25: 42 | D25: DIA 15 — PG MANUAL | F25: Consignado Nubank 2 | G25: 1.57% am | H25: 21.85% aa | I25: 96x — saldo R$776,82
A26: SANTANDER SX | B26: PLANO CLARO | C26: 73.73 | D26: DIA 09 — PG MANUAL | F26: Fin. Habitação CAIXA | G26: 7% nominal
A27: NU | B27: YOUTUBE ST | C27: 53.9 | D27: DIA 25 — CRÉDITO (NU) | F27: Empréstimo Sabrina | I27: saldo R$2.503,46
A28: NU | B28: ICLOUD | C28: 5.9 | D28: DIA 01 — CRÉDITO (NU) | F28: Empréstimo Josy
B29: Serasa | C29: 23.9 | D29: DIA 17 —
B30: Kindle | C30: 24
A31: NU | B31: GPT | C31: 130 | D31: DIA 02 — CRÉDITO (NU)
A32: NU | B32: Copilot | C32: 109.9 | D32: DIA 04 — CRÉDITO (NU)
A33: NU | B33: WORD | C33: 0 | D33: Anual — CRÉDITO (NU)
A34: NU | B34: GDRIVE EWE | C34: 0 | D34: Ago/26 — CRÉDITO (NU)
B35: PDFVIEW | C35: 0 | D35: CRÉDITO (NU)
A36: TOTAL ASSINATURAS | C36: =SUM(C24:C35)
A38: CHEQUE ESPECIAL / DÍVIDAS FINANCEIRAS
A39: BANCO | B39: LIMITE | C39: USADO | D39: JUROS MÊS | E39: TAXA % aa | F39: DIAS | G39: SITUAÇÃO
A40: BB
A41: Santander
...

Sheet Dez
A1: ORÇAMENTO DEZEMBRO 2026
A2: ▶ FONTES DE RECEITA | E2: ▶ DESCONTOS EM FOLHA | I2: ▶ DESPESAS FIXAS | O2: ▶ DESPESAS COM CARTÕES
A3: ORIGEM | B3: VALOR | C3: SITUAÇÃO | D3: DATA PG | E3: ORIGEM | F3: VALOR | G3: INFO | H3: OBS | I3: ORIGEM | J3: VALOR | K3: JUROS | L3: CET | M3: SITUAÇÃO | N3: DATA PG | O3: CARTÃO | P3: FATURA | Q3: PAGO | R3: SALDO¹ | S3: JUROS | T3: CET | U3: SITUAÇÃO | V3: DATA PG
A4: SALÁRIO | E4: Consignado V.Nbk | I4: HAPVIDA/SALMINHO | L4: =IF(J4="","",J4+IF(K4="",0,K4)) | O4: BB | R4: =IF(P4="","",P4-IF(Q4="",0,Q4)) | T4: =IF(Q4="","",Q4+IF(S4="",0,S4))
A5: Kalena OF/NET | E5: Caixa Habitação | I5: HAPVIDA/SABRINA | L5: =IF(J5="","",J5+IF(K5="",0,K5)) | O5: NU | R5: =IF(P5="","",P5-IF(Q5="",0,Q5)) | T5: =IF(Q5="","",Q5+IF(S5="",0,S5))
A6: ALUGUÉL | E6: Consignado BB | I6: HAP EWE E EFRA | L6: =IF(J6="","",J6+IF(K6="",0,K6)) | O6: Santander SX | R6: =IF(P6="","",P6-IF(Q6="",0,Q6)) | T6: =IF(Q6="","",Q6+IF(S6="",0,S6))
A7: Wagner | E7: Emp.Sal.BB | I7: CELPA ENERGIA | L7: =IF(J7="","",J7+IF(K7="",0,K7)) | O7: SELITE | R7: =IF(P7="","",P7-IF(Q7="",0,Q7)) | T7: =IF(Q7="","",Q7+IF(S7="",0,S7))
A8: Neto | E8: AUX.TRANSP | I8: SEATELECOM | L8: =IF(J8="","",J8+IF(K8="",0,K8)) | O8: Caixa Gold | R8: =IF(P8="","",P8-IF(Q8="",0,Q8)) | T8: =IF(Q8="","",Q8+IF(S8="",0,S8))
A9: UAB | E9: CONTRI.SOCIAL | I9: TX.ÁLAMO | L9: =IF(J9="","",J9+IF(K9="",0,K9)) | O9: Cartão MP | R9: =IF(P9="","",P9-IF(Q9="",0,Q9)) | T9: =IF(Q9="","",Q9+IF(S9="",0,S9))
E10: IRRF | I10: CONTA TIM | L10: =IF(J10="","",J10+IF(K10="",0,K10)) | O10: PicPay Card | R10: =IF(P10="","",P10-IF(Q10="",0,Q10)) | T10: =IF(Q10="","",Q10+IF(S10="",0,S10))
E11: AUX.PRÉ.ESC | I11: CONTA CLARO | L11: =IF(J11="","",J11+IF(K11="",0,K11)) | O11: Itaú Card | R11: =IF(P11="","",P11-IF(Q11="",0,Q11)) | T11: =IF(Q11="","",Q11+IF(S11="",0,S11))
E12: Dízimo | I12: MAXÍDOMINI | L12: =IF(J12="","",J12+IF(K12="",0,K12)) | O12: CAIXA ELO | R12: =IF(P12="","",P12-IF(Q12="",0,Q12)) | T12: =IF(Q12="","",Q12+IF(S12="",0,S12))
I13: COSANPA/ÁGUA | L13: =IF(J13="","",J13+IF(K13="",0,K13)) | O13: Bradesco | R13: =IF(P13="","",P13-IF(Q13="",0,Q13)) | T13: =IF(Q13="","",Q13+IF(S13="",0,S13))
I14: ESCOLA SALMOM | L14: =IF(J14="","",J14+IF(K14="",0,K14)) | O14: RecargaPay | R14: =IF(P14="","",P14-IF(Q14="",0,Q14)) | T14: =IF(Q14="","",Q14+IF(S14="",0,S14))
I15: CORECON | L15: =IF(J15="","",J15+IF(K15="",0,K15)) | O15: BipaCard | R15: =IF(P15="","",P15-IF(Q15="",0,Q15)) | T15: =IF(Q15="","",Q15+IF(S15="",0,S15))
I16: Boticário | L16: =IF(J16="","",J16+IF(K16="",0,K16)) | O16: InfinitCard | R16: =IF(P16="","",P16-IF(Q16="",0,Q16)) | T16: =IF(Q16="","",Q16+IF(S16="",0,S16))
I17: Rodobens | L17: =IF(J17="","",J17+IF(K17="",0,K17)) | O17: Pagbank | R17: =IF(P17="","",P17-IF(Q17="",0,Q17)) | T17: =IF(Q17="","",Q17+IF(S17="",0,S17))
L18: =IF(J18="","",J18+IF(K18="",0,K18)) | O18: TonCard | R18: =IF(P18="","",P18-IF(Q18="",0,Q18)) | T18: =IF(Q18="","",Q18+IF(S18="",0,S18))
L19: =IF(J19="","",J19+IF(K19="",0,K19)) | R19: =IF(P19="","",P19-IF(Q19="",0,Q19)) | T19: =IF(Q19="","",Q19+IF(S19="",0,S19))
A20: RECEITA TOTAL | B20: =SUM(B4:B19) | E20: TOTAL DESCONTOS | F20: =SUM(F4:F19) | I20: TOTAL FIXAS (CET) | J20: =SUM(J4:J19) | K20: =SUM(K4:K19) | L20: =SUM(L4:L19) | O20: TOTAL CARTÕES | P20: =SUM(P4:P19) | Q20: =SUM(Q4:Q19) | R20: =SUM(R4:R19) | S20: =SUM(S4:S19) | T20: =SUM(T4:T19)
O21: ¹ SALDO = Fatura − Pago (valor não quitado = nova dívida do mês)
A22: ASSINATURAS ONLINE | F22: NOTAS / EMPRÉSTIMOS / CONSIGNADOS
A23: CARTÃO | B23: SERVIÇO | C23: VALOR | D23: DIA/SITUAÇÃO | F23: DESCRIÇÃO | G23: TAXA (am) | H23: TAXA (aa) | I23: OBS / SALDO
